<mujoco model="j0">
  <default>
    <default class="/">
      <default class="small_joint">
        <joint group="3" type="hinge" pos="0 0 0.022222222222222223" limited="true" stiffness="135" range="-22 22" damping="10"/>
        <geom type="cylinder" size="0.125 0.011111111111111112" rgba="0.47058823529411764 0.47058823529411764 0.47058823529411764 0.69999999999999996"/>
      </default>
    </default>
    <default class="j1/">
      <default class="j1/small_joint">
        <joint group="3" type="hinge" pos="0 0 0.022222222222222223" limited="true" stiffness="135" range="-22 22" damping="10"/>
        <geom type="cylinder" size="0.10000000000000001 0.011111111111111112" rgba="0.47058823529411764 0.47058823529411764 0.47058823529411764 0.69999999999999996"/>
      </default>
    </default>
    <default class="j1/j2/">
      <default class="j1/j2/small_joint">
        <joint group="3" type="hinge" pos="0 0 0.022222222222222223" limited="true" stiffness="135" range="-22 22" damping="10"/>
        <geom type="cylinder" size="0.080000000000000002 0.011111111111111112" rgba="0.47058823529411764 0.47058823529411764 0.47058823529411764 0.69999999999999996"/>
      </default>
    </default>
  </default>
  <worldbody>
    <body name="j0_body0" childclass="small_joint" pos="0 0 0.011111111111111112" euler="0 0 0">
      <geom name="j0_geom0" group="1" rgba="0.29999999999999999 0.29999999999999999 0.29999999999999999 1"/>
      <inertial pos="0 0 0" mass="0.20000000000000001" diaginertia="0.0007894804526748972 0.0007894804526748972 0.0015625000000000001"/>
      <site name="j0_site0_chamber2" group="2" rgba="0 1 0 1" pos="0.069444444444444448 0 0"/>
      <site name="j0_site0_chamber3" group="3" rgba="0 1 0 1" pos="-0.069444444444444448 0 0"/>
      <site name="j0_site0_chamber0" group="0" rgba="0 1 0 1" pos="0 0.069444444444444448 0"/>
      <site name="j0_site0_chamber1" group="1" rgba="0 1 0 1" pos="0 -0.069444444444444448 0"/>
      <body name="j0_body1" pos="0 0 0.044444444444444446">
        <geom name="j0_geom1" group="1" rgba="0.29999999999999999 0.29999999999999999 0.29999999999999999 1"/>
        <inertial pos="0 0 0" mass="0.20000000000000001" diaginertia="0.0007894804526748972 0.0007894804526748972 0.0015625000000000001"/>
        <site name="j0_site1_chamber2" group="2" rgba="0 1 0 1" pos="0.069444444444444448 0 0"/>
        <site name="j0_site1_chamber3" group="3" rgba="0 1 0 1" pos="-0.069444444444444448 0 0"/>
        <site name="j0_site1_chamber0" group="0" rgba="0 1 0 1" pos="0 0.069444444444444448 0"/>
        <site name="j0_site1_chamber1" group="1" rgba="0 1 0 1" pos="0 -0.069444444444444448 0"/>
        <joint name="j0_jointX0" pos="0 0 -0.022222222222222223" axis="1 0 0"/>
        <joint name="j0_jointY0" pos="0 0 -0.022222222222222223" axis="0 1 0"/>
        <site name="j0_site1_rot" group="4" rgba="1 0 0 1" pos="0 0 -0.022222222222222223"/>
        <body name="j0_body2" pos="0 0 0.044444444444444446">
          <geom name="j0_geom2" group="1" rgba="0.29999999999999999 0.29999999999999999 0.29999999999999999 1"/>
          <inertial pos="0 0 0" mass="0.20000000000000001" diaginertia="0.0007894804526748972 0.0007894804526748972 0.0015625000000000001"/>
          <site name="j0_site2_chamber2" group="2" rgba="0 1 0 1" pos="0.069444444444444448 0 0"/>
          <site name="j0_site2_chamber3" group="3" rgba="0 1 0 1" pos="-0.069444444444444448 0 0"/>
          <site name="j0_site2_chamber0" group="0" rgba="0 1 0 1" pos="0 0.069444444444444448 0"/>
          <site name="j0_site2_chamber1" group="1" rgba="0 1 0 1" pos="0 -0.069444444444444448 0"/>
          <joint name="j0_jointX1" pos="0 0 -0.022222222222222223" axis="1 0 0"/>
          <joint name="j0_jointY1" pos="0 0 -0.022222222222222223" axis="0 1 0"/>
          <site name="j0_site2_rot" group="4" rgba="1 0 0 1" pos="0 0 -0.022222222222222223"/>
          <body name="j0_body3" pos="0 0 0.044444444444444446">
            <geom name="j0_geom3" group="1" rgba="0.29999999999999999 0.29999999999999999 0.29999999999999999 1"/>
            <inertial pos="0 0 0" mass="0.20000000000000001" diaginertia="0.0007894804526748972 0.0007894804526748972 0.0015625000000000001"/>
            <site name="j0_site3_chamber2" group="2" rgba="0 1 0 1" pos="0.069444444444444448 0 0"/>
            <site name="j0_site3_chamber3" group="3" rgba="0 1 0 1" pos="-0.069444444444444448 0 0"/>
            <site name="j0_site3_chamber0" group="0" rgba="0 1 0 1" pos="0 0.069444444444444448 0"/>
            <site name="j0_site3_chamber1" group="1" rgba="0 1 0 1" pos="0 -0.069444444444444448 0"/>
            <joint name="j0_jointX2" pos="0 0 -0.022222222222222223" axis="1 0 0"/>
            <joint name="j0_jointY2" pos="0 0 -0.022222222222222223" axis="0 1 0"/>
            <site name="j0_site3_rot" group="4" rgba="1 0 0 1" pos="0 0 -0.022222222222222223"/>
            <body name="j0_body4" pos="0 0 0.044444444444444446">
              <geom name="j0_geom4" group="1" rgba="0.29999999999999999 0.29999999999999999 0.29999999999999999 1"/>
              <inertial pos="0 0 0" mass="0.20000000000000001" diaginertia="0.0007894804526748972 0.0007894804526748972 0.0015625000000000001"/>
              <site name="j0_site4_chamber2" group="2" rgba="0 1 0 1" pos="0.069444444444444448 0 0"/>
              <site name="j0_site4_chamber3" group="3" rgba="0 1 0 1" pos="-0.069444444444444448 0 0"/>
              <site name="j0_site4_chamber0" group="0" rgba="0 1 0 1" pos="0 0.069444444444444448 0"/>
              <site name="j0_site4_chamber1" group="1" rgba="0 1 0 1" pos="0 -0.069444444444444448 0"/>
              <joint name="j0_jointX3" pos="0 0 -0.022222222222222223" axis="1 0 0"/>
              <joint name="j0_jointY3" pos="0 0 -0.022222222222222223" axis="0 1 0"/>
              <site name="j0_site4_rot" group="4" rgba="1 0 0 1" pos="0 0 -0.022222222222222223"/>
              <site name="j0_site4_chamber0_plus30" group="1" rgba="1 1 1 1" pos="-0.026575238358686786 0.064158300868839363 0"/>
              <site name="j0_site4_chamber0_minus30" group="1" rgba="1 1 1 1" pos="0.026575238358686786 0.064158300868839363 0"/>
              <site name="j0_site4_chamber1_plus30" group="1" rgba="1 1 1 1" pos="0.026575238358686786 -0.064158300868839363 0"/>
              <site name="j0_site4_chamber1_minus30" group="1" rgba="1 1 1 1" pos="-0.026575238358686786 -0.064158300868839363 0"/>
              <site name="j0_site4_chamber2_plus30" group="1" rgba="1 1 1 1" pos="0.064158300868839363 0.026575238358686786 0"/>
              <site name="j0_site4_chamber2_minus30" group="1" rgba="1 1 1 1" pos="0.064158300868839363 -0.026575238358686786 0"/>
              <site name="j0_site4_chamber3_plus30" group="1" rgba="1 1 1 1" pos="-0.064158300868839363 -0.026575238358686786 0"/>
              <site name="j0_site4_chamber3_minus30" group="1" rgba="1 1 1 1" pos="-0.064158300868839363 0.026575238358686786 0"/>
              <site name="j0_connection_site" rgba="1 1 0 1" pos="0 0 0.011111111111111112"/>
              <body pos="0 0 0.011111111111111112" name="j1/">
                <body name="j1/j1_body0" childclass="j1/small_joint" pos="0 0 0.011111111111111112" euler="0 0 0">
                  <geom name="j1/j1_geom0" group="1" rgba="0.29999999999999999 0.29999999999999999 0.29999999999999999 1"/>
                  <inertial pos="0 0 0" mass="0.20000000000000001" diaginertia="0.00050823045267489727 0.00050823045267489727 0.0010000000000000002"/>
                  <site name="j1/j1_site0_chamber2" group="2" rgba="0 1 0 1" pos="0.055555555555555559 0 0"/>
                  <site name="j1/j1_site0_chamber3" group="3" rgba="0 1 0 1" pos="-0.055555555555555559 0 0"/>
                  <site name="j1/j1_site0_chamber0" group="0" rgba="0 1 0 1" pos="0 0.055555555555555559 0"/>
                  <site name="j1/j1_site0_chamber1" group="1" rgba="0 1 0 1" pos="0 -0.055555555555555559 0"/>
                  <body name="j1/j1_body1" pos="0 0 0.044444444444444446">
                    <geom name="j1/j1_geom1" group="1" rgba="0.29999999999999999 0.29999999999999999 0.29999999999999999 1"/>
                    <inertial pos="0 0 0" mass="0.20000000000000001" diaginertia="0.00050823045267489727 0.00050823045267489727 0.0010000000000000002"/>
                    <site name="j1/j1_site1_chamber2" group="2" rgba="0 1 0 1" pos="0.055555555555555559 0 0"/>
                    <site name="j1/j1_site1_chamber3" group="3" rgba="0 1 0 1" pos="-0.055555555555555559 0 0"/>
                    <site name="j1/j1_site1_chamber0" group="0" rgba="0 1 0 1" pos="0 0.055555555555555559 0"/>
                    <site name="j1/j1_site1_chamber1" group="1" rgba="0 1 0 1" pos="0 -0.055555555555555559 0"/>
                    <joint name="j1/j1_jointX0" pos="0 0 -0.022222222222222223" axis="1 0 0"/>
                    <joint name="j1/j1_jointY0" pos="0 0 -0.022222222222222223" axis="0 1 0"/>
                    <site name="j1/j1_site1_rot" group="4" rgba="1 0 0 1" pos="0 0 -0.022222222222222223"/>
                    <body name="j1/j1_body2" pos="0 0 0.044444444444444446">
                      <geom name="j1/j1_geom2" group="1" rgba="0.29999999999999999 0.29999999999999999 0.29999999999999999 1"/>
                      <inertial pos="0 0 0" mass="0.20000000000000001" diaginertia="0.00050823045267489727 0.00050823045267489727 0.0010000000000000002"/>
                      <site name="j1/j1_site2_chamber2" group="2" rgba="0 1 0 1" pos="0.055555555555555559 0 0"/>
                      <site name="j1/j1_site2_chamber3" group="3" rgba="0 1 0 1" pos="-0.055555555555555559 0 0"/>
                      <site name="j1/j1_site2_chamber0" group="0" rgba="0 1 0 1" pos="0 0.055555555555555559 0"/>
                      <site name="j1/j1_site2_chamber1" group="1" rgba="0 1 0 1" pos="0 -0.055555555555555559 0"/>
                      <joint name="j1/j1_jointX1" pos="0 0 -0.022222222222222223" axis="1 0 0"/>
                      <joint name="j1/j1_jointY1" pos="0 0 -0.022222222222222223" axis="0 1 0"/>
                      <site name="j1/j1_site2_rot" group="4" rgba="1 0 0 1" pos="0 0 -0.022222222222222223"/>
                      <body name="j1/j1_body3" pos="0 0 0.044444444444444446">
                        <geom name="j1/j1_geom3" group="1" rgba="0.29999999999999999 0.29999999999999999 0.29999999999999999 1"/>
                        <inertial pos="0 0 0" mass="0.20000000000000001" diaginertia="0.00050823045267489727 0.00050823045267489727 0.0010000000000000002"/>
                        <site name="j1/j1_site3_chamber2" group="2" rgba="0 1 0 1" pos="0.055555555555555559 0 0"/>
                        <site name="j1/j1_site3_chamber3" group="3" rgba="0 1 0 1" pos="-0.055555555555555559 0 0"/>
                        <site name="j1/j1_site3_chamber0" group="0" rgba="0 1 0 1" pos="0 0.055555555555555559 0"/>
                        <site name="j1/j1_site3_chamber1" group="1" rgba="0 1 0 1" pos="0 -0.055555555555555559 0"/>
                        <joint name="j1/j1_jointX2" pos="0 0 -0.022222222222222223" axis="1 0 0"/>
                        <joint name="j1/j1_jointY2" pos="0 0 -0.022222222222222223" axis="0 1 0"/>
                        <site name="j1/j1_site3_rot" group="4" rgba="1 0 0 1" pos="0 0 -0.022222222222222223"/>
                        <body name="j1/j1_body4" pos="0 0 0.044444444444444446">
                          <geom name="j1/j1_geom4" group="1" rgba="0.29999999999999999 0.29999999999999999 0.29999999999999999 1"/>
                          <inertial pos="0 0 0" mass="0.20000000000000001" diaginertia="0.00050823045267489727 0.00050823045267489727 0.0010000000000000002"/>
                          <site name="j1/j1_site4_chamber2" group="2" rgba="0 1 0 1" pos="0.055555555555555559 0 0"/>
                          <site name="j1/j1_site4_chamber3" group="3" rgba="0 1 0 1" pos="-0.055555555555555559 0 0"/>
                          <site name="j1/j1_site4_chamber0" group="0" rgba="0 1 0 1" pos="0 0.055555555555555559 0"/>
                          <site name="j1/j1_site4_chamber1" group="1" rgba="0 1 0 1" pos="0 -0.055555555555555559 0"/>
                          <joint name="j1/j1_jointX3" pos="0 0 -0.022222222222222223" axis="1 0 0"/>
                          <joint name="j1/j1_jointY3" pos="0 0 -0.022222222222222223" axis="0 1 0"/>
                          <site name="j1/j1_site4_rot" group="4" rgba="1 0 0 1" pos="0 0 -0.022222222222222223"/>
                          <site name="j1/j1_connection_site" rgba="1 1 0 1" pos="0 0 0.011111111111111112"/>
                          <body pos="0 0 0.011111111111111112" name="j1/j2/">
                            <body name="j1/j2/j2_body0" childclass="j1/j2/small_joint" pos="0 0 0.011111111111111112" euler="0 0 0">
                              <geom name="j1/j2/j2_geom0" group="1" rgba="0.29999999999999999 0.29999999999999999 0.29999999999999999 1"/>
                              <inertial pos="0 0 0" mass="0.20000000000000001" diaginertia="0.00032823045267489718 0.00032823045267489718 0.00064000000000000005"/>
                              <site name="j1/j2/j2_site0_chamber2" group="2" rgba="0 1 0 1" pos="0.044444444444444446 0 0"/>
                              <site name="j1/j2/j2_site0_chamber3" group="3" rgba="0 1 0 1" pos="-0.044444444444444446 0 0"/>
                              <site name="j1/j2/j2_site0_chamber0" group="0" rgba="0 1 0 1" pos="0 0.044444444444444446 0"/>
                              <site name="j1/j2/j2_site0_chamber1" group="1" rgba="0 1 0 1" pos="0 -0.044444444444444446 0"/>
                              <body name="j1/j2/j2_body1" pos="0 0 0.044444444444444446">
                                <geom name="j1/j2/j2_geom1" group="1" rgba="0.29999999999999999 0.29999999999999999 0.29999999999999999 1"/>
                                <inertial pos="0 0 0" mass="0.20000000000000001" diaginertia="0.00032823045267489718 0.00032823045267489718 0.00064000000000000005"/>
                                <site name="j1/j2/j2_site1_chamber2" group="2" rgba="0 1 0 1" pos="0.044444444444444446 0 0"/>
                                <site name="j1/j2/j2_site1_chamber3" group="3" rgba="0 1 0 1" pos="-0.044444444444444446 0 0"/>
                                <site name="j1/j2/j2_site1_chamber0" group="0" rgba="0 1 0 1" pos="0 0.044444444444444446 0"/>
                                <site name="j1/j2/j2_site1_chamber1" group="1" rgba="0 1 0 1" pos="0 -0.044444444444444446 0"/>
                                <joint name="j1/j2/j2_jointX0" pos="0 0 -0.022222222222222223" axis="1 0 0"/>
                                <joint name="j1/j2/j2_jointY0" pos="0 0 -0.022222222222222223" axis="0 1 0"/>
                                <site name="j1/j2/j2_site1_rot" group="4" rgba="1 0 0 1" pos="0 0 -0.022222222222222223"/>
                                <body name="j1/j2/j2_body2" pos="0 0 0.044444444444444446">
                                  <geom name="j1/j2/j2_geom2" group="1" rgba="0.29999999999999999 0.29999999999999999 0.29999999999999999 1"/>
                                  <inertial pos="0 0 0" mass="0.20000000000000001" diaginertia="0.00032823045267489718 0.00032823045267489718 0.00064000000000000005"/>
                                  <site name="j1/j2/j2_site2_chamber2" group="2" rgba="0 1 0 1" pos="0.044444444444444446 0 0"/>
                                  <site name="j1/j2/j2_site2_chamber3" group="3" rgba="0 1 0 1" pos="-0.044444444444444446 0 0"/>
                                  <site name="j1/j2/j2_site2_chamber0" group="0" rgba="0 1 0 1" pos="0 0.044444444444444446 0"/>
                                  <site name="j1/j2/j2_site2_chamber1" group="1" rgba="0 1 0 1" pos="0 -0.044444444444444446 0"/>
                                  <joint name="j1/j2/j2_jointX1" pos="0 0 -0.022222222222222223" axis="1 0 0"/>
                                  <joint name="j1/j2/j2_jointY1" pos="0 0 -0.022222222222222223" axis="0 1 0"/>
                                  <site name="j1/j2/j2_site2_rot" group="4" rgba="1 0 0 1" pos="0 0 -0.022222222222222223"/>
                                  <body name="j1/j2/j2_body3" pos="0 0 0.044444444444444446">
                                    <geom name="j1/j2/j2_geom3" group="1" rgba="0.29999999999999999 0.29999999999999999 0.29999999999999999 1"/>
                                    <inertial pos="0 0 0" mass="0.20000000000000001" diaginertia="0.00032823045267489718 0.00032823045267489718 0.00064000000000000005"/>
                                    <site name="j1/j2/j2_site3_chamber2" group="2" rgba="0 1 0 1" pos="0.044444444444444446 0 0"/>
                                    <site name="j1/j2/j2_site3_chamber3" group="3" rgba="0 1 0 1" pos="-0.044444444444444446 0 0"/>
                                    <site name="j1/j2/j2_site3_chamber0" group="0" rgba="0 1 0 1" pos="0 0.044444444444444446 0"/>
                                    <site name="j1/j2/j2_site3_chamber1" group="1" rgba="0 1 0 1" pos="0 -0.044444444444444446 0"/>
                                    <joint name="j1/j2/j2_jointX2" pos="0 0 -0.022222222222222223" axis="1 0 0"/>
                                    <joint name="j1/j2/j2_jointY2" pos="0 0 -0.022222222222222223" axis="0 1 0"/>
                                    <site name="j1/j2/j2_site3_rot" group="4" rgba="1 0 0 1" pos="0 0 -0.022222222222222223"/>
                                    <body name="j1/j2/j2_body4" pos="0 0 0.044444444444444446">
                                      <geom name="j1/j2/j2_geom4" group="1" rgba="0.29999999999999999 0.29999999999999999 0.29999999999999999 1"/>
                                      <inertial pos="0 0 0" mass="0.20000000000000001" diaginertia="0.00032823045267489718 0.00032823045267489718 0.00064000000000000005"/>
                                      <site name="j1/j2/j2_site4_chamber2" group="2" rgba="0 1 0 1" pos="0.044444444444444446 0 0"/>
                                      <site name="j1/j2/j2_site4_chamber3" group="3" rgba="0 1 0 1" pos="-0.044444444444444446 0 0"/>
                                      <site name="j1/j2/j2_site4_chamber0" group="0" rgba="0 1 0 1" pos="0 0.044444444444444446 0"/>
                                      <site name="j1/j2/j2_site4_chamber1" group="1" rgba="0 1 0 1" pos="0 -0.044444444444444446 0"/>
                                      <joint name="j1/j2/j2_jointX3" pos="0 0 -0.022222222222222223" axis="1 0 0"/>
                                      <joint name="j1/j2/j2_jointY3" pos="0 0 -0.022222222222222223" axis="0 1 0"/>
                                      <site name="j1/j2/j2_site4_rot" group="4" rgba="1 0 0 1" pos="0 0 -0.022222222222222223"/>
                                    </body>
                                  </body>
                                </body>
                              </body>
                            </body>
                          </body>
                        </body>
                      </body>
                    </body>
                  </body>
                </body>
              </body>
            </body>
            <site name="j0_site3_chamber0_plus30" group="1" rgba="1 1 1 1" pos="-0.026575238358686786 0.064158300868839363 0"/>
            <site name="j0_site3_chamber0_minus30" group="1" rgba="1 1 1 1" pos="0.026575238358686786 0.064158300868839363 0"/>
            <site name="j0_site3_chamber1_plus30" group="1" rgba="1 1 1 1" pos="0.026575238358686786 -0.064158300868839363 0"/>
            <site name="j0_site3_chamber1_minus30" group="1" rgba="1 1 1 1" pos="-0.026575238358686786 -0.064158300868839363 0"/>
            <site name="j0_site3_chamber2_plus30" group="1" rgba="1 1 1 1" pos="0.064158300868839363 0.026575238358686786 0"/>
            <site name="j0_site3_chamber2_minus30" group="1" rgba="1 1 1 1" pos="0.064158300868839363 -0.026575238358686786 0"/>
            <site name="j0_site3_chamber3_plus30" group="1" rgba="1 1 1 1" pos="-0.064158300868839363 -0.026575238358686786 0"/>
            <site name="j0_site3_chamber3_minus30" group="1" rgba="1 1 1 1" pos="-0.064158300868839363 0.026575238358686786 0"/>
          </body>
          <site name="j0_site2_chamber0_plus30" group="1" rgba="1 1 1 1" pos="-0.026575238358686786 0.064158300868839363 0"/>
          <site name="j0_site2_chamber0_minus30" group="1" rgba="1 1 1 1" pos="0.026575238358686786 0.064158300868839363 0"/>
          <site name="j0_site2_chamber1_plus30" group="1" rgba="1 1 1 1" pos="0.026575238358686786 -0.064158300868839363 0"/>
          <site name="j0_site2_chamber1_minus30" group="1" rgba="1 1 1 1" pos="-0.026575238358686786 -0.064158300868839363 0"/>
          <site name="j0_site2_chamber2_plus30" group="1" rgba="1 1 1 1" pos="0.064158300868839363 0.026575238358686786 0"/>
          <site name="j0_site2_chamber2_minus30" group="1" rgba="1 1 1 1" pos="0.064158300868839363 -0.026575238358686786 0"/>
          <site name="j0_site2_chamber3_plus30" group="1" rgba="1 1 1 1" pos="-0.064158300868839363 -0.026575238358686786 0"/>
          <site name="j0_site2_chamber3_minus30" group="1" rgba="1 1 1 1" pos="-0.064158300868839363 0.026575238358686786 0"/>
        </body>
        <site name="j0_site1_chamber0_plus30" group="1" rgba="1 1 1 1" pos="-0.026575238358686786 0.064158300868839363 0"/>
        <site name="j0_site1_chamber0_minus30" group="1" rgba="1 1 1 1" pos="0.026575238358686786 0.064158300868839363 0"/>
        <site name="j0_site1_chamber1_plus30" group="1" rgba="1 1 1 1" pos="0.026575238358686786 -0.064158300868839363 0"/>
        <site name="j0_site1_chamber1_minus30" group="1" rgba="1 1 1 1" pos="-0.026575238358686786 -0.064158300868839363 0"/>
        <site name="j0_site1_chamber2_plus30" group="1" rgba="1 1 1 1" pos="0.064158300868839363 0.026575238358686786 0"/>
        <site name="j0_site1_chamber2_minus30" group="1" rgba="1 1 1 1" pos="0.064158300868839363 -0.026575238358686786 0"/>
        <site name="j0_site1_chamber3_plus30" group="1" rgba="1 1 1 1" pos="-0.064158300868839363 -0.026575238358686786 0"/>
        <site name="j0_site1_chamber3_minus30" group="1" rgba="1 1 1 1" pos="-0.064158300868839363 0.026575238358686786 0"/>
      </body>
      <site name="j0_site0_chamber0_plus30" group="1" rgba="1 1 1 1" pos="-0.026575238358686786 0.064158300868839363 0"/>
      <site name="j0_site0_chamber0_minus30" group="1" rgba="1 1 1 1" pos="0.026575238358686786 0.064158300868839363 0"/>
      <site name="j0_site0_chamber1_plus30" group="1" rgba="1 1 1 1" pos="0.026575238358686786 -0.064158300868839363 0"/>
      <site name="j0_site0_chamber1_minus30" group="1" rgba="1 1 1 1" pos="-0.026575238358686786 -0.064158300868839363 0"/>
      <site name="j0_site0_chamber2_plus30" group="1" rgba="1 1 1 1" pos="0.064158300868839363 0.026575238358686786 0"/>
      <site name="j0_site0_chamber2_minus30" group="1" rgba="1 1 1 1" pos="0.064158300868839363 -0.026575238358686786 0"/>
      <site name="j0_site0_chamber3_plus30" group="1" rgba="1 1 1 1" pos="-0.064158300868839363 -0.026575238358686786 0"/>
      <site name="j0_site0_chamber3_minus30" group="1" rgba="1 1 1 1" pos="-0.064158300868839363 0.026575238358686786 0"/>
    </body>
  </worldbody>
  <tendon>
    <spatial name="j0_tendon0" class="/" width="0.029999999999999999" rgba="0.59999999999999998 0.59999999999999998 0.59999999999999998 0">
      <site site="j0_site0_chamber0"/>
      <site site="j0_site1_chamber0"/>
      <site site="j0_site2_chamber0"/>
      <site site="j0_site3_chamber0"/>
      <site site="j0_site4_chamber0"/>
    </spatial>
    <spatial name="j0_tendon1" class="/" width="0.029999999999999999" rgba="0.59999999999999998 0.59999999999999998 0.59999999999999998 0">
      <site site="j0_site0_chamber1"/>
      <site site="j0_site1_chamber1"/>
      <site site="j0_site2_chamber1"/>
      <site site="j0_site3_chamber1"/>
      <site site="j0_site4_chamber1"/>
    </spatial>
    <spatial name="j0_tendon2" class="/" width="0.029999999999999999" rgba="0.59999999999999998 0.59999999999999998 0.59999999999999998 0">
      <site site="j0_site0_chamber2"/>
      <site site="j0_site1_chamber2"/>
      <site site="j0_site2_chamber2"/>
      <site site="j0_site3_chamber2"/>
      <site site="j0_site4_chamber2"/>
    </spatial>
    <spatial name="j0_tendon3" class="/" width="0.029999999999999999" rgba="0.59999999999999998 0.59999999999999998 0.59999999999999998 0">
      <site site="j0_site0_chamber3"/>
      <site site="j0_site1_chamber3"/>
      <site site="j0_site2_chamber3"/>
      <site site="j0_site3_chamber3"/>
      <site site="j0_site4_chamber3"/>
    </spatial>
    <spatial name="j0_tendon0_plus30" class="/" width="0.029999999999999999" rgba="0.59999999999999998 0.59999999999999998 0.59999999999999998 1">
      <site site="j0_site0_chamber0_plus30"/>
      <site site="j0_site1_chamber0_plus30"/>
      <site site="j0_site2_chamber0_plus30"/>
      <site site="j0_site3_chamber0_plus30"/>
      <site site="j0_site4_chamber0_plus30"/>
    </spatial>
    <spatial name="j0_tendon0_minus30" class="/" width="0.029999999999999999" rgba="0.59999999999999998 0.59999999999999998 0.59999999999999998 1">
      <site site="j0_site0_chamber0_minus30"/>
      <site site="j0_site1_chamber0_minus30"/>
      <site site="j0_site2_chamber0_minus30"/>
      <site site="j0_site3_chamber0_minus30"/>
      <site site="j0_site4_chamber0_minus30"/>
    </spatial>
    <spatial name="j0_tendon1_plus30" class="/" width="0.029999999999999999" rgba="0.59999999999999998 0.59999999999999998 0.59999999999999998 1">
      <site site="j0_site0_chamber1_plus30"/>
      <site site="j0_site1_chamber1_plus30"/>
      <site site="j0_site2_chamber1_plus30"/>
      <site site="j0_site3_chamber1_plus30"/>
      <site site="j0_site4_chamber1_plus30"/>
    </spatial>
    <spatial name="j0_tendon1_minus30" class="/" width="0.029999999999999999" rgba="0.59999999999999998 0.59999999999999998 0.59999999999999998 1">
      <site site="j0_site0_chamber1_minus30"/>
      <site site="j0_site1_chamber1_minus30"/>
      <site site="j0_site2_chamber1_minus30"/>
      <site site="j0_site3_chamber1_minus30"/>
      <site site="j0_site4_chamber1_minus30"/>
    </spatial>
    <spatial name="j0_tendon2_plus30" class="/" width="0.029999999999999999" rgba="0.59999999999999998 0.59999999999999998 0.59999999999999998 1">
      <site site="j0_site0_chamber2_plus30"/>
      <site site="j0_site1_chamber2_plus30"/>
      <site site="j0_site2_chamber2_plus30"/>
      <site site="j0_site3_chamber2_plus30"/>
      <site site="j0_site4_chamber2_plus30"/>
    </spatial>
    <spatial name="j0_tendon2_minus30" class="/" width="0.029999999999999999" rgba="0.59999999999999998 0.59999999999999998 0.59999999999999998 1">
      <site site="j0_site0_chamber2_minus30"/>
      <site site="j0_site1_chamber2_minus30"/>
      <site site="j0_site2_chamber2_minus30"/>
      <site site="j0_site3_chamber2_minus30"/>
      <site site="j0_site4_chamber2_minus30"/>
    </spatial>
    <spatial name="j0_tendon3_plus30" class="/" width="0.029999999999999999" rgba="0.59999999999999998 0.59999999999999998 0.59999999999999998 1">
      <site site="j0_site0_chamber3_plus30"/>
      <site site="j0_site1_chamber3_plus30"/>
      <site site="j0_site2_chamber3_plus30"/>
      <site site="j0_site3_chamber3_plus30"/>
      <site site="j0_site4_chamber3_plus30"/>
    </spatial>
    <spatial name="j0_tendon3_minus30" class="/" width="0.029999999999999999" rgba="0.59999999999999998 0.59999999999999998 0.59999999999999998 1">
      <site site="j0_site0_chamber3_minus30"/>
      <site site="j0_site1_chamber3_minus30"/>
      <site site="j0_site2_chamber3_minus30"/>
      <site site="j0_site3_chamber3_minus30"/>
      <site site="j0_site4_chamber3_minus30"/>
    </spatial>
    <spatial name="j1/j1_tendon0" class="j1/" width="0.029999999999999999" rgba="0.59999999999999998 0.59999999999999998 0.59999999999999998 1">
      <site site="j1/j1_site0_chamber0"/>
      <site site="j1/j1_site1_chamber0"/>
      <site site="j1/j1_site2_chamber0"/>
      <site site="j1/j1_site3_chamber0"/>
      <site site="j1/j1_site4_chamber0"/>
    </spatial>
    <spatial name="j1/j1_tendon1" class="j1/" width="0.029999999999999999" rgba="0.59999999999999998 0.59999999999999998 0.59999999999999998 1">
      <site site="j1/j1_site0_chamber1"/>
      <site site="j1/j1_site1_chamber1"/>
      <site site="j1/j1_site2_chamber1"/>
      <site site="j1/j1_site3_chamber1"/>
      <site site="j1/j1_site4_chamber1"/>
    </spatial>
    <spatial name="j1/j1_tendon2" class="j1/" width="0.029999999999999999" rgba="0.59999999999999998 0.59999999999999998 0.59999999999999998 1">
      <site site="j1/j1_site0_chamber2"/>
      <site site="j1/j1_site1_chamber2"/>
      <site site="j1/j1_site2_chamber2"/>
      <site site="j1/j1_site3_chamber2"/>
      <site site="j1/j1_site4_chamber2"/>
    </spatial>
    <spatial name="j1/j1_tendon3" class="j1/" width="0.029999999999999999" rgba="0.59999999999999998 0.59999999999999998 0.59999999999999998 1">
      <site site="j1/j1_site0_chamber3"/>
      <site site="j1/j1_site1_chamber3"/>
      <site site="j1/j1_site2_chamber3"/>
      <site site="j1/j1_site3_chamber3"/>
      <site site="j1/j1_site4_chamber3"/>
    </spatial>
    <spatial name="j1/j2/j2_tendon0" class="j1/j2/" width="0.029999999999999999" rgba="0.59999999999999998 0.59999999999999998 0.59999999999999998 1">
      <site site="j1/j2/j2_site0_chamber0"/>
      <site site="j1/j2/j2_site1_chamber0"/>
      <site site="j1/j2/j2_site2_chamber0"/>
      <site site="j1/j2/j2_site3_chamber0"/>
      <site site="j1/j2/j2_site4_chamber0"/>
    </spatial>
    <spatial name="j1/j2/j2_tendon1" class="j1/j2/" width="0.029999999999999999" rgba="0.59999999999999998 0.59999999999999998 0.59999999999999998 1">
      <site site="j1/j2/j2_site0_chamber1"/>
      <site site="j1/j2/j2_site1_chamber1"/>
      <site site="j1/j2/j2_site2_chamber1"/>
      <site site="j1/j2/j2_site3_chamber1"/>
      <site site="j1/j2/j2_site4_chamber1"/>
    </spatial>
    <spatial name="j1/j2/j2_tendon2" class="j1/j2/" width="0.029999999999999999" rgba="0.59999999999999998 0.59999999999999998 0.59999999999999998 1">
      <site site="j1/j2/j2_site0_chamber2"/>
      <site site="j1/j2/j2_site1_chamber2"/>
      <site site="j1/j2/j2_site2_chamber2"/>
      <site site="j1/j2/j2_site3_chamber2"/>
      <site site="j1/j2/j2_site4_chamber2"/>
    </spatial>
    <spatial name="j1/j2/j2_tendon3" class="j1/j2/" width="0.029999999999999999" rgba="0.59999999999999998 0.59999999999999998 0.59999999999999998 1">
      <site site="j1/j2/j2_site0_chamber3"/>
      <site site="j1/j2/j2_site1_chamber3"/>
      <site site="j1/j2/j2_site2_chamber3"/>
      <site site="j1/j2/j2_site3_chamber3"/>
      <site site="j1/j2/j2_site4_chamber3"/>
    </spatial>
  </tendon>
  <actuator>
    <cylinder name="j0_p0" class="/" ctrllimited="true" ctrlrange="0 1000" gear="500" tendon="j0_tendon0" timeconst="0.20000000000000001" diameter="0.050000000000000003"/>
    <cylinder name="j0_p1" class="/" ctrllimited="true" ctrlrange="0 1000" gear="500" tendon="j0_tendon1" timeconst="0.20000000000000001" diameter="0.050000000000000003"/>
    <cylinder name="j0_p2" class="/" ctrllimited="true" ctrlrange="0 1000" gear="500" tendon="j0_tendon2" timeconst="0.20000000000000001" diameter="0.050000000000000003"/>
    <cylinder name="j0_p3" class="/" ctrllimited="true" ctrlrange="0 1000" gear="500" tendon="j0_tendon3" timeconst="0.20000000000000001" diameter="0.050000000000000003"/>
    <cylinder name="j1/j1_p0" class="j1/" ctrllimited="true" ctrlrange="0 1000" gear="500" tendon="j1/j1_tendon0" timeconst="0.20000000000000001" diameter="0.050000000000000003"/>
    <cylinder name="j1/j1_p1" class="j1/" ctrllimited="true" ctrlrange="0 1000" gear="500" tendon="j1/j1_tendon1" timeconst="0.20000000000000001" diameter="0.050000000000000003"/>
    <cylinder name="j1/j1_p2" class="j1/" ctrllimited="true" ctrlrange="0 1000" gear="500" tendon="j1/j1_tendon2" timeconst="0.20000000000000001" diameter="0.050000000000000003"/>
    <cylinder name="j1/j1_p3" class="j1/" ctrllimited="true" ctrlrange="0 1000" gear="500" tendon="j1/j1_tendon3" timeconst="0.20000000000000001" diameter="0.050000000000000003"/>
    <cylinder name="j1/j2/j2_p0" class="j1/j2/" ctrllimited="true" ctrlrange="0 1000" gear="500" tendon="j1/j2/j2_tendon0" timeconst="0.20000000000000001" diameter="0.050000000000000003"/>
    <cylinder name="j1/j2/j2_p1" class="j1/j2/" ctrllimited="true" ctrlrange="0 1000" gear="500" tendon="j1/j2/j2_tendon1" timeconst="0.20000000000000001" diameter="0.050000000000000003"/>
    <cylinder name="j1/j2/j2_p2" class="j1/j2/" ctrllimited="true" ctrlrange="0 1000" gear="500" tendon="j1/j2/j2_tendon2" timeconst="0.20000000000000001" diameter="0.050000000000000003"/>
    <cylinder name="j1/j2/j2_p3" class="j1/j2/" ctrllimited="true" ctrlrange="0 1000" gear="500" tendon="j1/j2/j2_tendon3" timeconst="0.20000000000000001" diameter="0.050000000000000003"/>
  </actuator>
</mujoco>
