<mujoco model="SmallJoint">
  <compiler angle="degree"/>
  <option timestep="0.01" integrator="implicitfast" cone="elliptic" jacobian="sparse" solver="Newton">
    <flag gravity="enable"/>
  </option>
  <size njmax="5000" nconmax="5000" nstack="5000000"/>
  <visual>
    <map stiffness="100" fogstart="10" fogend="15" zfar="40" shadowscale="0.5"/>
    <scale forcewidth="0.10000000000000001" contactwidth="0.074999999999999997" contactheight="0.025000000000000001" framelength="0.59999999999999998" framewidth="0.059999999999999998"/>
  </visual>
  <default>
    <default class="/">
      <default class="small_joint">
        <joint group="3" type="hinge" pos="0 0 0.022222222222222223" limited="false" stiffness="40" damping="0.20000000000000001"/>
        <geom type="cylinder" size="0.080000000000000002 0.0055555555555555558" rgba="0.47058823529411764 0.47058823529411764 0.47058823529411764 0.69999999999999996"/>
      </default>
      <default class="bellows_site">
        <site rgba="0 1 0 1"/>
      </default>
      <default class="tendon">
        <tendon width="0.029999999999999999"/>
      </default>
    </default>
  </default>
  <extension>
    <plugin plugin="mujoco.sensor.joint_angle_estimator"/>
  </extension>
  <custom>
    <numeric name="num_disks" size="1" data="5"/>
  </custom>
  <asset>
    <texture name="texplane" type="2d" builtin="checker" mark="cross" width="512" height="512"/>
    <material name="matplane" class="/" texture="texplane" texuniform="true"/>
  </asset>
  <worldbody>
    <geom name="world" class="/" type="plane" condim="1" size="0 0 1" material="matplane"/>
    <light name="//unnamed_light_0" class="/" directional="true" pos="0 0 4" dir="0 0 -1" diffuse="0.59999999999999998 0.59999999999999998 0.59999999999999998" specular="0.20000000000000001 0.20000000000000001 0.20000000000000001"/>
    <camera name="fixedcam" class="/" pos="-1.357 2.722 2.4470000000000001" xyaxes="-0.88200000000000001 -0.47199999999999998 0 0.23799999999999999 -0.44600000000000001 0.86299999999999999"/>
    <body name="left_0_B0" childclass="small_joint" pos="0 0 0.011111111111111112" euler="0 0 0">
      <geom name="left_0_G0" class="small_joint"/>
      <inertial pos="0 0 0" mass="0.26519999999999999" diaginertia="0.00043523358024691365 0.00043523358024691365 0.00084864000000000001"/>
      <site name="left_0_xsite0" class="bellows_site" pos="0.040000000000000001 0 0"/>
      <site name="left_0_-xsite0" class="bellows_site" pos="-0.040000000000000001 0 0"/>
      <site name="left_0_ysite0" class="bellows_site" pos="0 0.040000000000000001 0"/>
      <site name="left_0_-ysite0" class="bellows_site" pos="0 -0.040000000000000001 0"/>
      <body name="left_0_B1" pos="0 0 0.044444444444444446">
        <geom name="left_0_G1"/>
        <inertial pos="0 0 0" mass="0.26519999999999999" diaginertia="0.00043523358024691365 0.00043523358024691365 0.00084864000000000001"/>
        <joint name="left_0_Jx_0" pos="0 0 -0.022222222222222223" axis="1 0 0"/>
        <joint name="left_0_Jy_0" pos="0 0 -0.022222222222222223" axis="0 1 0"/>
        <site name="left_0_xsite1" class="bellows_site" pos="0.040000000000000001 0 0"/>
        <site name="left_0_-xsite1" class="bellows_site" pos="-0.040000000000000001 0 0"/>
        <site name="left_0_ysite1" class="bellows_site" pos="0 0.040000000000000001 0"/>
        <site name="left_0_-ysite1" class="bellows_site" pos="0 -0.040000000000000001 0"/>
        <body name="left_0_B2" pos="0 0 0.044444444444444446">
          <geom name="left_0_G2"/>
          <inertial pos="0 0 0" mass="0.26519999999999999" diaginertia="0.00043523358024691365 0.00043523358024691365 0.00084864000000000001"/>
          <joint name="left_0_Jx_1" pos="0 0 -0.022222222222222223" axis="1 0 0"/>
          <joint name="left_0_Jy_1" pos="0 0 -0.022222222222222223" axis="0 1 0"/>
          <site name="left_0_xsite2" class="bellows_site" pos="0.040000000000000001 0 0"/>
          <site name="left_0_-xsite2" class="bellows_site" pos="-0.040000000000000001 0 0"/>
          <site name="left_0_ysite2" class="bellows_site" pos="0 0.040000000000000001 0"/>
          <site name="left_0_-ysite2" class="bellows_site" pos="0 -0.040000000000000001 0"/>
          <body name="left_0_B3" pos="0 0 0.044444444444444446">
            <geom name="left_0_G3"/>
            <inertial pos="0 0 0" mass="0.26519999999999999" diaginertia="0.00043523358024691365 0.00043523358024691365 0.00084864000000000001"/>
            <joint name="left_0_Jx_2" pos="0 0 -0.022222222222222223" axis="1 0 0"/>
            <joint name="left_0_Jy_2" pos="0 0 -0.022222222222222223" axis="0 1 0"/>
            <site name="left_0_xsite3" class="bellows_site" pos="0.040000000000000001 0 0"/>
            <site name="left_0_-xsite3" class="bellows_site" pos="-0.040000000000000001 0 0"/>
            <site name="left_0_ysite3" class="bellows_site" pos="0 0.040000000000000001 0"/>
            <site name="left_0_-ysite3" class="bellows_site" pos="0 -0.040000000000000001 0"/>
            <body name="left_0_B4" pos="0 0 0.044444444444444446">
              <geom name="left_0_G4"/>
              <inertial pos="0 0 0" mass="0.26519999999999999" diaginertia="0.00043523358024691365 0.00043523358024691365 0.00084864000000000001"/>
              <joint name="left_0_Jx_3" pos="0 0 -0.022222222222222223" axis="1 0 0"/>
              <joint name="left_0_Jy_3" pos="0 0 -0.022222222222222223" axis="0 1 0"/>
              <site name="left_0_xsite4" class="bellows_site" pos="0.040000000000000001 0 0"/>
              <site name="left_0_-xsite4" class="bellows_site" pos="-0.040000000000000001 0 0"/>
              <site name="left_0_ysite4" class="bellows_site" pos="0 0.040000000000000001 0"/>
              <site name="left_0_-ysite4" class="bellows_site" pos="0 -0.040000000000000001 0"/>
            </body>
          </body>
        </body>
      </body>
    </body>
  </worldbody>
  <tendon>
    <spatial name="bellows0" class="tendon">
      <site site="left_0_ysite0"/>
      <site site="left_0_ysite1"/>
      <site site="left_0_ysite2"/>
      <site site="left_0_ysite3"/>
      <site site="left_0_ysite4"/>
    </spatial>
    <spatial name="bellows1" class="tendon">
      <site site="left_0_-ysite0"/>
      <site site="left_0_-ysite1"/>
      <site site="left_0_-ysite2"/>
      <site site="left_0_-ysite3"/>
      <site site="left_0_-ysite4"/>
    </spatial>
    <spatial name="bellows2" class="tendon">
      <site site="left_0_-xsite0"/>
      <site site="left_0_-xsite1"/>
      <site site="left_0_-xsite2"/>
      <site site="left_0_-xsite3"/>
      <site site="left_0_-xsite4"/>
    </spatial>
    <spatial name="bellows3" class="tendon">
      <site site="left_0_xsite0"/>
      <site site="left_0_xsite1"/>
      <site site="left_0_xsite2"/>
      <site site="left_0_xsite3"/>
      <site site="left_0_xsite4"/>
    </spatial>
  </tendon>
  <actuator>
    <cylinder name="p0" class="/" ctrllimited="true" ctrlrange="0 1000" gear="500" tendon="bellows0" timeconst="0.20000000000000001" diameter="0.050000000000000003"/>
    <cylinder name="p1" class="/" ctrllimited="true" ctrlrange="0 1000" gear="500" tendon="bellows1" timeconst="0.20000000000000001" diameter="0.050000000000000003"/>
    <cylinder name="p2" class="/" ctrllimited="true" ctrlrange="0 1000" gear="500" tendon="bellows2" timeconst="0.20000000000000001" diameter="0.050000000000000003"/>
    <cylinder name="p3" class="/" ctrllimited="true" ctrlrange="0 1000" gear="500" tendon="bellows3" timeconst="0.20000000000000001" diameter="0.050000000000000003"/>
  </actuator>
  <sensor>
    <framequat name="left_0_B0_framequat" objtype="body" objname="left_0_B0"/>
    <framequat name="left_0_B4_framequat" objtype="body" objname="left_0_B4"/>
    <frameangvel name="left_0_B4_frameangvel" objtype="body" objname="left_0_B4" reftype="body" refname="left_0_B0"/>
    <plugin name="left_0" plugin="mujoco.sensor.joint_angle_estimator"/>
  </sensor>
</mujoco>
