<mujoco model="baloo_v0.2.0">
  <compiler angle="degree" discardvisual="true"/>
  <option timestep="0.01" integrator="implicitfast" cone="elliptic" jacobian="auto" solver="Newton" iterations="10">
    <flag gravity="enable" multiccd="enable"/>
  </option>
  <size memory="-1"/>
  <visual>
    <map stiffness="100" force="0.10000000000000001" fogstart="10" fogend="15" zfar="40" shadowscale="0.5"/>
    <scale forcewidth="0.10000000000000001" contactwidth="0.074999999999999997" contactheight="0.025000000000000001" framelength="0.59999999999999998" framewidth="0.059999999999999998"/>
  </visual>
  <default>
    <default class="/">
      <default class="large_joint">
        <joint group="0" type="hinge" pos="0 0 -0.032142857142857147" limited="true" stiffness="270" range="-30 30" damping="15"/>
        <geom type="cylinder" size="0.128 0.016071428571428573" rgba="0.47058823529411764 0.47058823529411764 0.47058823529411764 0.69999999999999996"/>
      </default>
      <default class="medium_joint">
        <joint group="0" type="hinge" pos="0 0 -0.032142857142857147" limited="true" stiffness="150" range="-36.666666666666664 36.666666666666664" damping="15"/>
        <geom type="cylinder" size="0.10199999999999999 0.016071428571428573" rgba="0.47058823529411764 0.47058823529411764 0.47058823529411764 0.69999999999999996"/>
      </default>
      <default class="small_joint">
        <joint group="0" type="hinge" pos="0 0 -0.032142857142857147" limited="true" stiffness="90" range="-36.666666666666664 36.666666666666664" damping="3"/>
        <geom type="cylinder" size="0.088999999999999996 0.016071428571428573" rgba="0.47058823529411764 0.47058823529411764 0.47058823529411764 0.69999999999999996"/>
      </default>
      <default class="bellows_site">
        <site rgba="0 1 0 1"/>
      </default>
      <default class="tendon">
        <tendon width="0.029999999999999999"/>
      </default>
      <default class="cylinder">
        <cylinder ctrllimited="true" ctrlrange="0 400"/>
      </default>
      <default class="taxel_geom">
        <geom type="sphere" contype="0" conaffinity="2" condim="4" group="1" size="0.0074999999999999997" rgba="0.19607843137254902 0.19607843137254902 0.19607843137254902 0.69999999999999996"/>
      </default>
      <default class="taxel_site">
        <site type="sphere" group="1" rgba="0.19607843137254902 0.19607843137254902 0.19607843137254902 0.69999999999999996" size="0.0074999999999999997"/>
      </default>
    </default>
  </default>
  <extension>
    <plugin plugin="mujoco.sensor.joint_angle_estimator"/>
    <plugin plugin="mujoco.actuator.ruckig_actuator"/>
  </extension>
  <custom>
    <numeric name="num_disks" size="1" data="4"/>
  </custom>
  <asset>
    <texture name="texplane" type="2d" builtin="checker" mark="cross" width="512" height="512"/>
    <material name="groundplane" class="/" texture="texplane" texuniform="true"/>
    <texture name="chest_texture" type="2d" file="/home/curtis/baloo/baloo-mujoco-sim/src/baloo_mujoco_sim/assets/meshes/SimpleChestColors.png"/>
    <material name="chest_material" class="/" texture="chest_texture"/>
    <mesh name="RightFrontWheelMesh" class="/" file="/home/curtis/baloo/baloo-mujoco-sim/src/baloo_mujoco_sim/assets/meshes/RightFrontWheelMesh.stl"/>
    <mesh name="EstopPlugMesh" class="/" file="/home/curtis/baloo/baloo-mujoco-sim/src/baloo_mujoco_sim/assets/meshes/EstopPlugMesh.stl"/>
    <mesh name="LeftBackWheelMesh" class="/" file="/home/curtis/baloo/baloo-mujoco-sim/src/baloo_mujoco_sim/assets/meshes/LeftBackWheelMesh.stl"/>
    <mesh name="PowerButtonMesh" class="/" file="/home/curtis/baloo/baloo-mujoco-sim/src/baloo_mujoco_sim/assets/meshes/PowerButtonMesh.stl"/>
    <mesh name="EthernetJackMesh" class="/" file="/home/curtis/baloo/baloo-mujoco-sim/src/baloo_mujoco_sim/assets/meshes/EthernetJackMesh.stl"/>
    <mesh name="StepperMesh" class="/" file="/home/curtis/baloo/baloo-mujoco-sim/src/baloo_mujoco_sim/assets/meshes/StepperMesh.stl"/>
    <mesh name="LinearActuatorMesh" class="/" file="/home/curtis/baloo/baloo-mujoco-sim/src/baloo_mujoco_sim/assets/meshes/LinearActuatorMesh.stl"/>
    <mesh name="RightBackWheelMesh" class="/" file="/home/curtis/baloo/baloo-mujoco-sim/src/baloo_mujoco_sim/assets/meshes/RightBackWheelMesh.stl"/>
    <mesh name="PneumaticInletMesh" class="/" file="/home/curtis/baloo/baloo-mujoco-sim/src/baloo_mujoco_sim/assets/meshes/PneumaticInletMesh.stl"/>
    <mesh name="ControlBoxMesh" class="/" file="/home/curtis/baloo/baloo-mujoco-sim/src/baloo_mujoco_sim/assets/meshes/ControlBoxMesh.stl"/>
    <mesh name="LeftBackWheelFootMesh" class="/" file="/home/curtis/baloo/baloo-mujoco-sim/src/baloo_mujoco_sim/assets/meshes/LeftBackWheelFootMesh.stl"/>
    <mesh name="meshed_cube" class="/" file="/home/curtis/baloo/baloo-mujoco-sim/src/baloo_mujoco_sim/assets/meshes/meshed_cube.stl"/>
    <mesh name="LeftBaseMesh" class="/" file="/home/curtis/baloo/baloo-mujoco-sim/src/baloo_mujoco_sim/assets/meshes/LeftBaseMesh.stl"/>
    <mesh name="BaseFrameMesh" class="/" file="/home/curtis/baloo/baloo-mujoco-sim/src/baloo_mujoco_sim/assets/meshes/BaseFrameMesh.stl"/>
    <mesh name="SimpleShoulderMesh" class="/" file="/home/curtis/baloo/baloo-mujoco-sim/src/baloo_mujoco_sim/assets/meshes/SimpleShoulderMesh.stl"/>
    <mesh name="LeftFrontWheelMesh" class="/" file="/home/curtis/baloo/baloo-mujoco-sim/src/baloo_mujoco_sim/assets/meshes/LeftFrontWheelMesh.stl"/>
    <mesh name="RightFrontWheelFootMesh" class="/" file="/home/curtis/baloo/baloo-mujoco-sim/src/baloo_mujoco_sim/assets/meshes/RightFrontWheelFootMesh.stl"/>
    <mesh name="LeftFrontWheelFootMesh" class="/" file="/home/curtis/baloo/baloo-mujoco-sim/src/baloo_mujoco_sim/assets/meshes/LeftFrontWheelFootMesh.stl"/>
    <mesh name="SimpleChestMesh" class="/" file="/home/curtis/baloo/baloo-mujoco-sim/src/baloo_mujoco_sim/assets/meshes/SimpleChestMesh.obj"/>
    <mesh name="LCDScreenMesh" class="/" file="/home/curtis/baloo/baloo-mujoco-sim/src/baloo_mujoco_sim/assets/meshes/LCDScreenMesh.stl"/>
    <mesh name="RightBaseMesh" class="/" file="/home/curtis/baloo/baloo-mujoco-sim/src/baloo_mujoco_sim/assets/meshes/RightBaseMesh.stl"/>
    <mesh name="RightBackWheelFootMesh" class="/" file="/home/curtis/baloo/baloo-mujoco-sim/src/baloo_mujoco_sim/assets/meshes/RightBackWheelFootMesh.stl"/>
    <material name="vention_blue" class="/" reflectance="1" rgba="0 0.15686274509803921 0.31372549019607843 1"/>
    <material name="matte_black" class="/" reflectance="0.20000000000000001" rgba="0 0 0 1"/>
    <material name="cream" class="/" reflectance="0.20000000000000001" rgba="0.90000000000000002 0.90000000000000002 0.90000000000000002 1"/>
    <material name="silver" class="/" reflectance="0.80000000000000004" rgba="0.80000000000000004 0.80000000000000004 0.80000000000000004 1"/>
    <material name="red" class="/" reflectance="0.80000000000000004" rgba="0.80000000000000004 0.20000000000000001 0.20000000000000001 1"/>
    <material name="lcd_blue" class="/" reflectance="0.80000000000000004" rgba="0.20000000000000001 0.20000000000000001 0.80000000000000004 1"/>
    <material name="green" class="/" reflectance="0.80000000000000004" rgba="0.20000000000000001 0.80000000000000004 0.20000000000000001 1"/>
  </asset>
  <worldbody>
    <geom name="world" class="/" type="plane" condim="4" size="0 0 1" material="groundplane"/>
    <light name="//unnamed_light_0" class="/" directional="true" pos="0 0 4" dir="0 0 -1" diffuse="0.59999999999999998 0.59999999999999998 0.59999999999999998" specular="0.20000000000000001 0.20000000000000001 0.20000000000000001"/>
    <camera name="fixedcam" class="/" pos="-1.357 2.722 2.4470000000000001" xyaxes="-0.88200000000000001 -0.47199999999999998 0 0.23799999999999999 -0.44600000000000001 0.86299999999999999"/>
    <camera name="frontcam" class="/" pos="-0 3.0819999999999999 2.1179999999999999" xyaxes="-1 -0.0089999999999999993 0 0.0040000000000000001 -0.41699999999999998 0.90900000000000003"/>
    <body name="box" pos="0 0.5 0.375" euler="0 0 0">
      <geom name="box" class="/" type="box" contype="2" conaffinity="1" size="0.125 0.125 0.375" rgba="0.80000000000000004 0.20000000000000001 0.10000000000000001 1" pos="0 0 0"/>
      <inertial pos="0 0 0" mass="5" diaginertia="0.052083333333333336 0.26041666666666669 0.26041666666666669"/>
      <freejoint name="//unnamed_joint_0"/>
    </body>
    <body name="base" pos="0 0 0" euler="0 0 0">
      <geom name="base::left_leg" class="/" type="mesh" contype="0" conaffinity="1" material="vention_blue" mesh="LeftBaseMesh"/>
      <geom name="base::right_leg" class="/" type="mesh" contype="0" conaffinity="1" material="vention_blue" mesh="RightBaseMesh"/>
      <geom name="base" class="/" type="mesh" material="vention_blue" mesh="BaseFrameMesh"/>
      <geom name="base::linear_actuator" class="/" type="mesh" material="vention_blue" mesh="LinearActuatorMesh"/>
      <geom name="base::pneumatic_inlet" class="/" type="mesh" contype="0" conaffinity="0" material="silver" mesh="PneumaticInletMesh"/>
      <geom name="base::power_button" class="/" type="mesh" contype="0" conaffinity="0" material="red" mesh="PowerButtonMesh"/>
      <geom name="base::control_box" class="/" type="mesh" contype="0" conaffinity="0" material="matte_black" mesh="ControlBoxMesh"/>
      <geom name="base::estop_plug" class="/" type="mesh" contype="0" conaffinity="0" material="green" mesh="EstopPlugMesh"/>
      <geom name="base::ethernet_jack" class="/" type="mesh" contype="0" conaffinity="0" material="silver" mesh="EthernetJackMesh"/>
      <geom name="base::lcd_screen" class="/" type="mesh" contype="0" conaffinity="0" material="lcd_blue" mesh="LCDScreenMesh"/>
      <geom name="base::left_back_wheel_foot" class="/" type="mesh" contype="0" conaffinity="0" material="matte_black" mesh="LeftBackWheelFootMesh"/>
      <geom name="base::left_front_wheel_foot" class="/" type="mesh" contype="0" conaffinity="0" material="matte_black" mesh="LeftFrontWheelFootMesh"/>
      <geom name="base::right_back_wheel_foot" class="/" type="mesh" contype="0" conaffinity="0" material="matte_black" mesh="RightBackWheelFootMesh"/>
      <geom name="base::right_front_wheel_foot" class="/" type="mesh" contype="0" conaffinity="0" material="matte_black" mesh="RightFrontWheelFootMesh"/>
      <geom name="base::left_back_wheel" class="/" type="mesh" contype="0" conaffinity="0" material="cream" mesh="LeftBackWheelMesh"/>
      <geom name="base::left_front_wheel" class="/" type="mesh" contype="0" conaffinity="0" material="cream" mesh="LeftFrontWheelMesh"/>
      <geom name="base::right_back_wheel" class="/" type="mesh" contype="0" conaffinity="0" material="cream" mesh="RightBackWheelMesh"/>
      <geom name="base::right_front_wheel" class="/" type="mesh" contype="0" conaffinity="0" material="cream" mesh="RightFrontWheelMesh"/>
      <geom name="base::stepper_motor" class="/" type="mesh" contype="0" conaffinity="0" material="matte_black" mesh="StepperMesh"/>
      <body name="chest" pos="0 0.19500000000000001 1.554" euler="0 0 0">
        <geom name="chest" class="/" type="mesh" material="chest_material" mesh="SimpleChestMesh"/>
        <inertial pos="0 0 0" mass="5" diaginertia="0.13104833333333335 0.053763333333333337 0.13104833333333335"/>
        <joint name="chest::linear_actuator" class="/" type="slide" axis="0 0 1" limited="true" range="-1.2 0" damping="500"/>
        <body name="chest::tactile_sensor"/>
        <body name="chest::right_shoulder" pos="0.42499999999999999 0 0" euler="67.5 0 0">
          <geom name="chest::right_shoulder" class="/" type="mesh" contype="0" conaffinity="0" material="silver" mesh="SimpleShoulderMesh"/>
          <inertial pos="0 0 0" mass="0.013599999999999999" diaginertia="0.0008497 0.0008497 0.0016992000000000001"/>
          <body name="right_arm::j0::B0" pos="0 0 -0.20107142857142857" euler="180 0 -45">
            <geom name="right_arm::j0::disk0" class="large_joint"/>
            <inertial pos="0 0 0" mass="1.1575" diaginertia="0.0048407772066326529 0.0048407772066326529 0.0094822399999999994"/>
            <site name="right_arm::j0::b0::site0" class="bellows_site" pos="0 0.074999999999999997 0"/>
            <site name="right_arm::j0::b0::site1" class="bellows_site" pos="0 -0.074999999999999997 0"/>
            <site name="right_arm::j0::b0::site2" class="bellows_site" pos="-0.074999999999999997 0 0"/>
            <site name="right_arm::j0::b0::site3" class="bellows_site" pos="0.074999999999999997 0 0"/>
            <site name="right_arm::j0::b0::site0_A" class="/" rgba="1 1 1 1" pos="-0.028701257427381728 0.069290964938346508 0"/>
            <site name="right_arm::j0::b0::site0_B" class="/" group="0" rgba="1 1 1 1" pos="0.028701257427381728 0.069290964938346508 0"/>
            <site name="right_arm::j0::b0::site1_A" class="/" rgba="1 1 1 1" pos="0.028701257427381728 -0.069290964938346508 0"/>
            <site name="right_arm::j0::b0::site1_B" class="/" group="0" rgba="1 1 1 1" pos="-0.028701257427381728 -0.069290964938346508 0"/>
            <site name="right_arm::j0::b0::site2_A" class="/" rgba="1 1 1 1" pos="-0.069290964938346508 -0.028701257427381728 0"/>
            <site name="right_arm::j0::b0::site2_B" class="/" group="0" rgba="1 1 1 1" pos="-0.069290964938346508 0.028701257427381728 0"/>
            <site name="right_arm::j0::b0::site3_A" class="/" rgba="1 1 1 1" pos="0.069290964938346508 0.028701257427381728 0"/>
            <site name="right_arm::j0::b0::site3_B" class="/" group="0" rgba="1 1 1 1" pos="0.069290964938346508 -0.028701257427381728 0"/>
            <body name="right_arm::j0::B1" pos="0 0 0.064285714285714293">
              <geom name="right_arm::j0::disk1" class="large_joint"/>
              <inertial pos="0 0 0" mass="1.1575" diaginertia="0.0048407772066326529 0.0048407772066326529 0.0094822399999999994"/>
              <joint name="right_arm::j0::Jx_0" class="large_joint" axis="1 0 0"/>
              <joint name="right_arm::j0::Jy_0" class="large_joint" axis="0 1 0"/>
              <site name="right_arm::j0::b1::site0" class="bellows_site" pos="0 0.074999999999999997 0"/>
              <site name="right_arm::j0::b1::site1" class="bellows_site" pos="0 -0.074999999999999997 0"/>
              <site name="right_arm::j0::b1::site2" class="bellows_site" pos="-0.074999999999999997 0 0"/>
              <site name="right_arm::j0::b1::site3" class="bellows_site" pos="0.074999999999999997 0 0"/>
              <site name="right_arm::j0::b1::site0_A" class="/" rgba="1 1 1 1" pos="-0.028701257427381728 0.069290964938346508 0"/>
              <site name="right_arm::j0::b1::site0_B" class="/" group="0" rgba="1 1 1 1" pos="0.028701257427381728 0.069290964938346508 0"/>
              <site name="right_arm::j0::b1::site1_A" class="/" rgba="1 1 1 1" pos="0.028701257427381728 -0.069290964938346508 0"/>
              <site name="right_arm::j0::b1::site1_B" class="/" group="0" rgba="1 1 1 1" pos="-0.028701257427381728 -0.069290964938346508 0"/>
              <site name="right_arm::j0::b1::site2_A" class="/" rgba="1 1 1 1" pos="-0.069290964938346508 -0.028701257427381728 0"/>
              <site name="right_arm::j0::b1::site2_B" class="/" group="0" rgba="1 1 1 1" pos="-0.069290964938346508 0.028701257427381728 0"/>
              <site name="right_arm::j0::b1::site3_A" class="/" rgba="1 1 1 1" pos="0.069290964938346508 0.028701257427381728 0"/>
              <site name="right_arm::j0::b1::site3_B" class="/" group="0" rgba="1 1 1 1" pos="0.069290964938346508 -0.028701257427381728 0"/>
              <body name="right_arm::j0::B2" pos="0 0 0.064285714285714293">
                <geom name="right_arm::j0::disk2" class="large_joint"/>
                <inertial pos="0 0 0" mass="1.1575" diaginertia="0.0048407772066326529 0.0048407772066326529 0.0094822399999999994"/>
                <joint name="right_arm::j0::Jx_1" class="large_joint" axis="1 0 0"/>
                <joint name="right_arm::j0::Jy_1" class="large_joint" axis="0 1 0"/>
                <site name="right_arm::j0::b2::site0" class="bellows_site" pos="0 0.074999999999999997 0"/>
                <site name="right_arm::j0::b2::site1" class="bellows_site" pos="0 -0.074999999999999997 0"/>
                <site name="right_arm::j0::b2::site2" class="bellows_site" pos="-0.074999999999999997 0 0"/>
                <site name="right_arm::j0::b2::site3" class="bellows_site" pos="0.074999999999999997 0 0"/>
                <site name="right_arm::j0::b2::site0_A" class="/" rgba="1 1 1 1" pos="-0.028701257427381728 0.069290964938346508 0"/>
                <site name="right_arm::j0::b2::site0_B" class="/" group="0" rgba="1 1 1 1" pos="0.028701257427381728 0.069290964938346508 0"/>
                <site name="right_arm::j0::b2::site1_A" class="/" rgba="1 1 1 1" pos="0.028701257427381728 -0.069290964938346508 0"/>
                <site name="right_arm::j0::b2::site1_B" class="/" group="0" rgba="1 1 1 1" pos="-0.028701257427381728 -0.069290964938346508 0"/>
                <site name="right_arm::j0::b2::site2_A" class="/" rgba="1 1 1 1" pos="-0.069290964938346508 -0.028701257427381728 0"/>
                <site name="right_arm::j0::b2::site2_B" class="/" group="0" rgba="1 1 1 1" pos="-0.069290964938346508 0.028701257427381728 0"/>
                <site name="right_arm::j0::b2::site3_A" class="/" rgba="1 1 1 1" pos="0.069290964938346508 0.028701257427381728 0"/>
                <site name="right_arm::j0::b2::site3_B" class="/" group="0" rgba="1 1 1 1" pos="0.069290964938346508 -0.028701257427381728 0"/>
                <body name="right_arm::j0::B3" pos="0 0 0.064285714285714293">
                  <geom name="right_arm::j0::disk3" class="large_joint"/>
                  <inertial pos="0 0 0" mass="1.1575" diaginertia="0.0048407772066326529 0.0048407772066326529 0.0094822399999999994"/>
                  <joint name="right_arm::j0::Jx_2" class="large_joint" axis="1 0 0"/>
                  <joint name="right_arm::j0::Jy_2" class="large_joint" axis="0 1 0"/>
                  <site name="right_arm::j0::b3::site0" class="bellows_site" pos="0 0.074999999999999997 0"/>
                  <site name="right_arm::j0::b3::site1" class="bellows_site" pos="0 -0.074999999999999997 0"/>
                  <site name="right_arm::j0::b3::site2" class="bellows_site" pos="-0.074999999999999997 0 0"/>
                  <site name="right_arm::j0::b3::site3" class="bellows_site" pos="0.074999999999999997 0 0"/>
                  <site name="right_arm::j0::b3::site0_A" class="/" rgba="1 1 1 1" pos="-0.028701257427381728 0.069290964938346508 0"/>
                  <site name="right_arm::j0::b3::site0_B" class="/" group="0" rgba="1 1 1 1" pos="0.028701257427381728 0.069290964938346508 0"/>
                  <site name="right_arm::j0::b3::site1_A" class="/" rgba="1 1 1 1" pos="0.028701257427381728 -0.069290964938346508 0"/>
                  <site name="right_arm::j0::b3::site1_B" class="/" group="0" rgba="1 1 1 1" pos="-0.028701257427381728 -0.069290964938346508 0"/>
                  <site name="right_arm::j0::b3::site2_A" class="/" rgba="1 1 1 1" pos="-0.069290964938346508 -0.028701257427381728 0"/>
                  <site name="right_arm::j0::b3::site2_B" class="/" group="0" rgba="1 1 1 1" pos="-0.069290964938346508 0.028701257427381728 0"/>
                  <site name="right_arm::j0::b3::site3_A" class="/" rgba="1 1 1 1" pos="0.069290964938346508 0.028701257427381728 0"/>
                  <site name="right_arm::j0::b3::site3_B" class="/" group="0" rgba="1 1 1 1" pos="0.069290964938346508 -0.028701257427381728 0"/>
                  <body name="right_arm::link0" pos="0 0 0.12057142857142857" euler="0 0 -45">
                    <geom name="right_arm::link0" class="/" type="cylinder" size="0.14499999999999999 0.1045" rgba="0 0 0 1"/>
                    <inertial pos="0 0 0.0075000000000000067" mass="4.54" diaginertia="0.040389353333333329 0.040389353333333329 0.047726749999999998"/>
                    <body name="right_arm::j1::B0" pos="0 0 0.12057142857142857" euler="0 0 45">
                      <geom name="right_arm::j1::disk0" class="medium_joint"/>
                      <inertial pos="0 0 0" mass="0.50749999999999995" diaginertia="0.0013637016964285712 0.0013637016964285712 0.0026400149999999995"/>
                      <site name="right_arm::j1::b0::site0" class="bellows_site" pos="0 0.059999999999999998 0"/>
                      <site name="right_arm::j1::b0::site1" class="bellows_site" pos="0 -0.059999999999999998 0"/>
                      <site name="right_arm::j1::b0::site2" class="bellows_site" pos="-0.059999999999999998 0 0"/>
                      <site name="right_arm::j1::b0::site3" class="bellows_site" pos="0.059999999999999998 0 0"/>
                      <body name="right_arm::j1::B1" pos="0 0 0.064285714285714293">
                        <geom name="right_arm::j1::disk1" class="medium_joint"/>
                        <inertial pos="0 0 0" mass="0.50749999999999995" diaginertia="0.0013637016964285712 0.0013637016964285712 0.0026400149999999995"/>
                        <joint name="right_arm::j1::Jx_0" class="medium_joint" axis="1 0 0"/>
                        <joint name="right_arm::j1::Jy_0" class="medium_joint" axis="0 1 0"/>
                        <site name="right_arm::j1::b1::site0" class="bellows_site" pos="0 0.059999999999999998 0"/>
                        <site name="right_arm::j1::b1::site1" class="bellows_site" pos="0 -0.059999999999999998 0"/>
                        <site name="right_arm::j1::b1::site2" class="bellows_site" pos="-0.059999999999999998 0 0"/>
                        <site name="right_arm::j1::b1::site3" class="bellows_site" pos="0.059999999999999998 0 0"/>
                        <body name="right_arm::j1::B2" pos="0 0 0.064285714285714293">
                          <geom name="right_arm::j1::disk2" class="medium_joint"/>
                          <inertial pos="0 0 0" mass="0.50749999999999995" diaginertia="0.0013637016964285712 0.0013637016964285712 0.0026400149999999995"/>
                          <joint name="right_arm::j1::Jx_1" class="medium_joint" axis="1 0 0"/>
                          <joint name="right_arm::j1::Jy_1" class="medium_joint" axis="0 1 0"/>
                          <site name="right_arm::j1::b2::site0" class="bellows_site" pos="0 0.059999999999999998 0"/>
                          <site name="right_arm::j1::b2::site1" class="bellows_site" pos="0 -0.059999999999999998 0"/>
                          <site name="right_arm::j1::b2::site2" class="bellows_site" pos="-0.059999999999999998 0 0"/>
                          <site name="right_arm::j1::b2::site3" class="bellows_site" pos="0.059999999999999998 0 0"/>
                          <body name="right_arm::j1::B3" pos="0 0 0.064285714285714293">
                            <geom name="right_arm::j1::disk3" class="medium_joint"/>
                            <inertial pos="0 0 0" mass="0.50749999999999995" diaginertia="0.0013637016964285712 0.0013637016964285712 0.0026400149999999995"/>
                            <joint name="right_arm::j1::Jx_2" class="medium_joint" axis="1 0 0"/>
                            <joint name="right_arm::j1::Jy_2" class="medium_joint" axis="0 1 0"/>
                            <site name="right_arm::j1::b3::site0" class="bellows_site" pos="0 0.059999999999999998 0"/>
                            <site name="right_arm::j1::b3::site1" class="bellows_site" pos="0 -0.059999999999999998 0"/>
                            <site name="right_arm::j1::b3::site2" class="bellows_site" pos="-0.059999999999999998 0 0"/>
                            <site name="right_arm::j1::b3::site3" class="bellows_site" pos="0.059999999999999998 0 0"/>
                            <body name="right_arm::link1" pos="0 0 0.10057142857142858" euler="0 0 -45">
                              <geom name="right_arm::link1" class="/" type="cylinder" size="0.12 0.084500000000000006" rgba="0 0 0 1"/>
                              <inertial pos="0 0 0.0024999999999999883" mass="2.214" diaginertia="0.013239904500000002 0.013239904500000002 0.015940799999999998"/>
                              <body name="right_arm::j2::B0" pos="0 0 0.096071428571428572" euler="0 0 45">
                                <geom name="right_arm::j2::disk0" class="small_joint"/>
                                <inertial pos="0 0 0" mass="0.41249999999999998" diaginertia="0.00085236811224489789 0.00085236811224489789 0.0016337062499999998"/>
                                <site name="right_arm::j2::b0::site0" class="bellows_site" pos="0 0.040000000000000001 0"/>
                                <site name="right_arm::j2::b0::site1" class="bellows_site" pos="0 -0.040000000000000001 0"/>
                                <site name="right_arm::j2::b0::site2" class="bellows_site" pos="-0.040000000000000001 0 0"/>
                                <site name="right_arm::j2::b0::site3" class="bellows_site" pos="0.040000000000000001 0 0"/>
                                <body name="right_arm::j2::B1" pos="0 0 0.064285714285714293">
                                  <geom name="right_arm::j2::disk1" class="small_joint"/>
                                  <inertial pos="0 0 0" mass="0.41249999999999998" diaginertia="0.00085236811224489789 0.00085236811224489789 0.0016337062499999998"/>
                                  <joint name="right_arm::j2::Jx_0" class="small_joint" axis="1 0 0"/>
                                  <joint name="right_arm::j2::Jy_0" class="small_joint" axis="0 1 0"/>
                                  <site name="right_arm::j2::b1::site0" class="bellows_site" pos="0 0.040000000000000001 0"/>
                                  <site name="right_arm::j2::b1::site1" class="bellows_site" pos="0 -0.040000000000000001 0"/>
                                  <site name="right_arm::j2::b1::site2" class="bellows_site" pos="-0.040000000000000001 0 0"/>
                                  <site name="right_arm::j2::b1::site3" class="bellows_site" pos="0.040000000000000001 0 0"/>
                                  <body name="right_arm::j2::B2" pos="0 0 0.064285714285714293">
                                    <geom name="right_arm::j2::disk2" class="small_joint"/>
                                    <inertial pos="0 0 0" mass="0.41249999999999998" diaginertia="0.00085236811224489789 0.00085236811224489789 0.0016337062499999998"/>
                                    <joint name="right_arm::j2::Jx_1" class="small_joint" axis="1 0 0"/>
                                    <joint name="right_arm::j2::Jy_1" class="small_joint" axis="0 1 0"/>
                                    <site name="right_arm::j2::b2::site0" class="bellows_site" pos="0 0.040000000000000001 0"/>
                                    <site name="right_arm::j2::b2::site1" class="bellows_site" pos="0 -0.040000000000000001 0"/>
                                    <site name="right_arm::j2::b2::site2" class="bellows_site" pos="-0.040000000000000001 0 0"/>
                                    <site name="right_arm::j2::b2::site3" class="bellows_site" pos="0.040000000000000001 0 0"/>
                                    <body name="right_arm::j2::B3" pos="0 0 0.064285714285714293">
                                      <geom name="right_arm::j2::disk3" class="small_joint"/>
                                      <inertial pos="0 0 0" mass="0.41249999999999998" diaginertia="0.00085236811224489789 0.00085236811224489789 0.0016337062499999998"/>
                                      <joint name="right_arm::j2::Jx_2" class="small_joint" axis="1 0 0"/>
                                      <joint name="right_arm::j2::Jy_2" class="small_joint" axis="0 1 0"/>
                                      <site name="right_arm::j2::b3::site0" class="bellows_site" pos="0 0.040000000000000001 0"/>
                                      <site name="right_arm::j2::b3::site1" class="bellows_site" pos="0 -0.040000000000000001 0"/>
                                      <site name="right_arm::j2::b3::site2" class="bellows_site" pos="-0.040000000000000001 0 0"/>
                                      <site name="right_arm::j2::b3::site3" class="bellows_site" pos="0.040000000000000001 0 0"/>
                                    </body>
                                  </body>
                                </body>
                              </body>
                            </body>
                          </body>
                        </body>
                      </body>
                    </body>
                  </body>
                </body>
              </body>
            </body>
          </body>
        </body>
        <body name="chest::left_shoulder" pos="-0.42499999999999999 0 0" euler="67.5 0 0">
          <geom name="chest::left_shoulder" class="/" type="mesh" contype="0" conaffinity="0" material="silver" euler="0 0 180" mesh="SimpleShoulderMesh"/>
          <inertial pos="0 0 0" mass="0.013599999999999999" diaginertia="0.0008497 0.0008497 0.0016992000000000001"/>
          <body name="left_arm::j0::B0" pos="0 0 -0.20107142857142857" euler="180 0 -45">
            <geom name="left_arm::j0::disk0" class="large_joint"/>
            <inertial pos="0 0 0" mass="1.1575" diaginertia="0.0048407772066326529 0.0048407772066326529 0.0094822399999999994"/>
            <site name="left_arm::j0::b0::site0" class="bellows_site" pos="0 0.074999999999999997 0"/>
            <site name="left_arm::j0::b0::site1" class="bellows_site" pos="0 -0.074999999999999997 0"/>
            <site name="left_arm::j0::b0::site2" class="bellows_site" pos="-0.074999999999999997 0 0"/>
            <site name="left_arm::j0::b0::site3" class="bellows_site" pos="0.074999999999999997 0 0"/>
            <site name="left_arm::j0::b0::site0_A" class="/" rgba="1 1 1 1" pos="-0.028701257427381728 0.069290964938346508 0"/>
            <site name="left_arm::j0::b0::site0_B" class="/" group="0" rgba="1 1 1 1" pos="0.028701257427381728 0.069290964938346508 0"/>
            <site name="left_arm::j0::b0::site1_A" class="/" rgba="1 1 1 1" pos="0.028701257427381728 -0.069290964938346508 0"/>
            <site name="left_arm::j0::b0::site1_B" class="/" group="0" rgba="1 1 1 1" pos="-0.028701257427381728 -0.069290964938346508 0"/>
            <site name="left_arm::j0::b0::site2_A" class="/" rgba="1 1 1 1" pos="-0.069290964938346508 -0.028701257427381728 0"/>
            <site name="left_arm::j0::b0::site2_B" class="/" group="0" rgba="1 1 1 1" pos="-0.069290964938346508 0.028701257427381728 0"/>
            <site name="left_arm::j0::b0::site3_A" class="/" rgba="1 1 1 1" pos="0.069290964938346508 0.028701257427381728 0"/>
            <site name="left_arm::j0::b0::site3_B" class="/" group="0" rgba="1 1 1 1" pos="0.069290964938346508 -0.028701257427381728 0"/>
            <body name="left_arm::j0::B1" pos="0 0 0.064285714285714293">
              <geom name="left_arm::j0::disk1" class="large_joint"/>
              <inertial pos="0 0 0" mass="1.1575" diaginertia="0.0048407772066326529 0.0048407772066326529 0.0094822399999999994"/>
              <joint name="left_arm::j0::Jx_0" class="large_joint" axis="1 0 0"/>
              <joint name="left_arm::j0::Jy_0" class="large_joint" axis="0 1 0"/>
              <site name="left_arm::j0::b1::site0" class="bellows_site" pos="0 0.074999999999999997 0"/>
              <site name="left_arm::j0::b1::site1" class="bellows_site" pos="0 -0.074999999999999997 0"/>
              <site name="left_arm::j0::b1::site2" class="bellows_site" pos="-0.074999999999999997 0 0"/>
              <site name="left_arm::j0::b1::site3" class="bellows_site" pos="0.074999999999999997 0 0"/>
              <site name="left_arm::j0::b1::site0_A" class="/" rgba="1 1 1 1" pos="-0.028701257427381728 0.069290964938346508 0"/>
              <site name="left_arm::j0::b1::site0_B" class="/" group="0" rgba="1 1 1 1" pos="0.028701257427381728 0.069290964938346508 0"/>
              <site name="left_arm::j0::b1::site1_A" class="/" rgba="1 1 1 1" pos="0.028701257427381728 -0.069290964938346508 0"/>
              <site name="left_arm::j0::b1::site1_B" class="/" group="0" rgba="1 1 1 1" pos="-0.028701257427381728 -0.069290964938346508 0"/>
              <site name="left_arm::j0::b1::site2_A" class="/" rgba="1 1 1 1" pos="-0.069290964938346508 -0.028701257427381728 0"/>
              <site name="left_arm::j0::b1::site2_B" class="/" group="0" rgba="1 1 1 1" pos="-0.069290964938346508 0.028701257427381728 0"/>
              <site name="left_arm::j0::b1::site3_A" class="/" rgba="1 1 1 1" pos="0.069290964938346508 0.028701257427381728 0"/>
              <site name="left_arm::j0::b1::site3_B" class="/" group="0" rgba="1 1 1 1" pos="0.069290964938346508 -0.028701257427381728 0"/>
              <body name="left_arm::j0::B2" pos="0 0 0.064285714285714293">
                <geom name="left_arm::j0::disk2" class="large_joint"/>
                <inertial pos="0 0 0" mass="1.1575" diaginertia="0.0048407772066326529 0.0048407772066326529 0.0094822399999999994"/>
                <joint name="left_arm::j0::Jx_1" class="large_joint" axis="1 0 0"/>
                <joint name="left_arm::j0::Jy_1" class="large_joint" axis="0 1 0"/>
                <site name="left_arm::j0::b2::site0" class="bellows_site" pos="0 0.074999999999999997 0"/>
                <site name="left_arm::j0::b2::site1" class="bellows_site" pos="0 -0.074999999999999997 0"/>
                <site name="left_arm::j0::b2::site2" class="bellows_site" pos="-0.074999999999999997 0 0"/>
                <site name="left_arm::j0::b2::site3" class="bellows_site" pos="0.074999999999999997 0 0"/>
                <site name="left_arm::j0::b2::site0_A" class="/" rgba="1 1 1 1" pos="-0.028701257427381728 0.069290964938346508 0"/>
                <site name="left_arm::j0::b2::site0_B" class="/" group="0" rgba="1 1 1 1" pos="0.028701257427381728 0.069290964938346508 0"/>
                <site name="left_arm::j0::b2::site1_A" class="/" rgba="1 1 1 1" pos="0.028701257427381728 -0.069290964938346508 0"/>
                <site name="left_arm::j0::b2::site1_B" class="/" group="0" rgba="1 1 1 1" pos="-0.028701257427381728 -0.069290964938346508 0"/>
                <site name="left_arm::j0::b2::site2_A" class="/" rgba="1 1 1 1" pos="-0.069290964938346508 -0.028701257427381728 0"/>
                <site name="left_arm::j0::b2::site2_B" class="/" group="0" rgba="1 1 1 1" pos="-0.069290964938346508 0.028701257427381728 0"/>
                <site name="left_arm::j0::b2::site3_A" class="/" rgba="1 1 1 1" pos="0.069290964938346508 0.028701257427381728 0"/>
                <site name="left_arm::j0::b2::site3_B" class="/" group="0" rgba="1 1 1 1" pos="0.069290964938346508 -0.028701257427381728 0"/>
                <body name="left_arm::j0::B3" pos="0 0 0.064285714285714293">
                  <geom name="left_arm::j0::disk3" class="large_joint"/>
                  <inertial pos="0 0 0" mass="1.1575" diaginertia="0.0048407772066326529 0.0048407772066326529 0.0094822399999999994"/>
                  <joint name="left_arm::j0::Jx_2" class="large_joint" axis="1 0 0"/>
                  <joint name="left_arm::j0::Jy_2" class="large_joint" axis="0 1 0"/>
                  <site name="left_arm::j0::b3::site0" class="bellows_site" pos="0 0.074999999999999997 0"/>
                  <site name="left_arm::j0::b3::site1" class="bellows_site" pos="0 -0.074999999999999997 0"/>
                  <site name="left_arm::j0::b3::site2" class="bellows_site" pos="-0.074999999999999997 0 0"/>
                  <site name="left_arm::j0::b3::site3" class="bellows_site" pos="0.074999999999999997 0 0"/>
                  <site name="left_arm::j0::b3::site0_A" class="/" rgba="1 1 1 1" pos="-0.028701257427381728 0.069290964938346508 0"/>
                  <site name="left_arm::j0::b3::site0_B" class="/" group="0" rgba="1 1 1 1" pos="0.028701257427381728 0.069290964938346508 0"/>
                  <site name="left_arm::j0::b3::site1_A" class="/" rgba="1 1 1 1" pos="0.028701257427381728 -0.069290964938346508 0"/>
                  <site name="left_arm::j0::b3::site1_B" class="/" group="0" rgba="1 1 1 1" pos="-0.028701257427381728 -0.069290964938346508 0"/>
                  <site name="left_arm::j0::b3::site2_A" class="/" rgba="1 1 1 1" pos="-0.069290964938346508 -0.028701257427381728 0"/>
                  <site name="left_arm::j0::b3::site2_B" class="/" group="0" rgba="1 1 1 1" pos="-0.069290964938346508 0.028701257427381728 0"/>
                  <site name="left_arm::j0::b3::site3_A" class="/" rgba="1 1 1 1" pos="0.069290964938346508 0.028701257427381728 0"/>
                  <site name="left_arm::j0::b3::site3_B" class="/" group="0" rgba="1 1 1 1" pos="0.069290964938346508 -0.028701257427381728 0"/>
                  <body name="left_arm::link0" pos="0 0 0.12057142857142857" euler="0 0 -45">
                    <geom name="left_arm::link0" class="/" type="cylinder" size="0.14499999999999999 0.1045" rgba="0 0 0 1"/>
                    <inertial pos="0 0 0.0075000000000000067" mass="4.54" diaginertia="0.040389353333333329 0.040389353333333329 0.047726749999999998"/>
                    <body name="left_arm::j1::B0" pos="0 0 0.12057142857142857" euler="0 0 45">
                      <geom name="left_arm::j1::disk0" class="medium_joint"/>
                      <inertial pos="0 0 0" mass="0.50749999999999995" diaginertia="0.0013637016964285712 0.0013637016964285712 0.0026400149999999995"/>
                      <site name="left_arm::j1::b0::site0" class="bellows_site" pos="0 0.059999999999999998 0"/>
                      <site name="left_arm::j1::b0::site1" class="bellows_site" pos="0 -0.059999999999999998 0"/>
                      <site name="left_arm::j1::b0::site2" class="bellows_site" pos="-0.059999999999999998 0 0"/>
                      <site name="left_arm::j1::b0::site3" class="bellows_site" pos="0.059999999999999998 0 0"/>
                      <body name="left_arm::j1::B1" pos="0 0 0.064285714285714293">
                        <geom name="left_arm::j1::disk1" class="medium_joint"/>
                        <inertial pos="0 0 0" mass="0.50749999999999995" diaginertia="0.0013637016964285712 0.0013637016964285712 0.0026400149999999995"/>
                        <joint name="left_arm::j1::Jx_0" class="medium_joint" axis="1 0 0"/>
                        <joint name="left_arm::j1::Jy_0" class="medium_joint" axis="0 1 0"/>
                        <site name="left_arm::j1::b1::site0" class="bellows_site" pos="0 0.059999999999999998 0"/>
                        <site name="left_arm::j1::b1::site1" class="bellows_site" pos="0 -0.059999999999999998 0"/>
                        <site name="left_arm::j1::b1::site2" class="bellows_site" pos="-0.059999999999999998 0 0"/>
                        <site name="left_arm::j1::b1::site3" class="bellows_site" pos="0.059999999999999998 0 0"/>
                        <body name="left_arm::j1::B2" pos="0 0 0.064285714285714293">
                          <geom name="left_arm::j1::disk2" class="medium_joint"/>
                          <inertial pos="0 0 0" mass="0.50749999999999995" diaginertia="0.0013637016964285712 0.0013637016964285712 0.0026400149999999995"/>
                          <joint name="left_arm::j1::Jx_1" class="medium_joint" axis="1 0 0"/>
                          <joint name="left_arm::j1::Jy_1" class="medium_joint" axis="0 1 0"/>
                          <site name="left_arm::j1::b2::site0" class="bellows_site" pos="0 0.059999999999999998 0"/>
                          <site name="left_arm::j1::b2::site1" class="bellows_site" pos="0 -0.059999999999999998 0"/>
                          <site name="left_arm::j1::b2::site2" class="bellows_site" pos="-0.059999999999999998 0 0"/>
                          <site name="left_arm::j1::b2::site3" class="bellows_site" pos="0.059999999999999998 0 0"/>
                          <body name="left_arm::j1::B3" pos="0 0 0.064285714285714293">
                            <geom name="left_arm::j1::disk3" class="medium_joint"/>
                            <inertial pos="0 0 0" mass="0.50749999999999995" diaginertia="0.0013637016964285712 0.0013637016964285712 0.0026400149999999995"/>
                            <joint name="left_arm::j1::Jx_2" class="medium_joint" axis="1 0 0"/>
                            <joint name="left_arm::j1::Jy_2" class="medium_joint" axis="0 1 0"/>
                            <site name="left_arm::j1::b3::site0" class="bellows_site" pos="0 0.059999999999999998 0"/>
                            <site name="left_arm::j1::b3::site1" class="bellows_site" pos="0 -0.059999999999999998 0"/>
                            <site name="left_arm::j1::b3::site2" class="bellows_site" pos="-0.059999999999999998 0 0"/>
                            <site name="left_arm::j1::b3::site3" class="bellows_site" pos="0.059999999999999998 0 0"/>
                            <body name="left_arm::link1" pos="0 0 0.10057142857142858" euler="0 0 -45">
                              <geom name="left_arm::link1" class="/" type="cylinder" size="0.12 0.084500000000000006" rgba="0 0 0 1"/>
                              <inertial pos="0 0 0.0024999999999999883" mass="2.214" diaginertia="0.013239904500000002 0.013239904500000002 0.015940799999999998"/>
                              <body name="left_arm::j2::B0" pos="0 0 0.096071428571428572" euler="0 0 45">
                                <geom name="left_arm::j2::disk0" class="small_joint"/>
                                <inertial pos="0 0 0" mass="0.41249999999999998" diaginertia="0.00085236811224489789 0.00085236811224489789 0.0016337062499999998"/>
                                <site name="left_arm::j2::b0::site0" class="bellows_site" pos="0 0.040000000000000001 0"/>
                                <site name="left_arm::j2::b0::site1" class="bellows_site" pos="0 -0.040000000000000001 0"/>
                                <site name="left_arm::j2::b0::site2" class="bellows_site" pos="-0.040000000000000001 0 0"/>
                                <site name="left_arm::j2::b0::site3" class="bellows_site" pos="0.040000000000000001 0 0"/>
                                <body name="left_arm::j2::B1" pos="0 0 0.064285714285714293">
                                  <geom name="left_arm::j2::disk1" class="small_joint"/>
                                  <inertial pos="0 0 0" mass="0.41249999999999998" diaginertia="0.00085236811224489789 0.00085236811224489789 0.0016337062499999998"/>
                                  <joint name="left_arm::j2::Jx_0" class="small_joint" axis="1 0 0"/>
                                  <joint name="left_arm::j2::Jy_0" class="small_joint" axis="0 1 0"/>
                                  <site name="left_arm::j2::b1::site0" class="bellows_site" pos="0 0.040000000000000001 0"/>
                                  <site name="left_arm::j2::b1::site1" class="bellows_site" pos="0 -0.040000000000000001 0"/>
                                  <site name="left_arm::j2::b1::site2" class="bellows_site" pos="-0.040000000000000001 0 0"/>
                                  <site name="left_arm::j2::b1::site3" class="bellows_site" pos="0.040000000000000001 0 0"/>
                                  <body name="left_arm::j2::B2" pos="0 0 0.064285714285714293">
                                    <geom name="left_arm::j2::disk2" class="small_joint"/>
                                    <inertial pos="0 0 0" mass="0.41249999999999998" diaginertia="0.00085236811224489789 0.00085236811224489789 0.0016337062499999998"/>
                                    <joint name="left_arm::j2::Jx_1" class="small_joint" axis="1 0 0"/>
                                    <joint name="left_arm::j2::Jy_1" class="small_joint" axis="0 1 0"/>
                                    <site name="left_arm::j2::b2::site0" class="bellows_site" pos="0 0.040000000000000001 0"/>
                                    <site name="left_arm::j2::b2::site1" class="bellows_site" pos="0 -0.040000000000000001 0"/>
                                    <site name="left_arm::j2::b2::site2" class="bellows_site" pos="-0.040000000000000001 0 0"/>
                                    <site name="left_arm::j2::b2::site3" class="bellows_site" pos="0.040000000000000001 0 0"/>
                                    <body name="left_arm::j2::B3" pos="0 0 0.064285714285714293">
                                      <geom name="left_arm::j2::disk3" class="small_joint"/>
                                      <inertial pos="0 0 0" mass="0.41249999999999998" diaginertia="0.00085236811224489789 0.00085236811224489789 0.0016337062499999998"/>
                                      <joint name="left_arm::j2::Jx_2" class="small_joint" axis="1 0 0"/>
                                      <joint name="left_arm::j2::Jy_2" class="small_joint" axis="0 1 0"/>
                                      <site name="left_arm::j2::b3::site0" class="bellows_site" pos="0 0.040000000000000001 0"/>
                                      <site name="left_arm::j2::b3::site1" class="bellows_site" pos="0 -0.040000000000000001 0"/>
                                      <site name="left_arm::j2::b3::site2" class="bellows_site" pos="-0.040000000000000001 0 0"/>
                                      <site name="left_arm::j2::b3::site3" class="bellows_site" pos="0.040000000000000001 0 0"/>
                                    </body>
                                  </body>
                                </body>
                              </body>
                            </body>
                          </body>
                        </body>
                      </body>
                    </body>
                  </body>
                </body>
              </body>
            </body>
          </body>
        </body>
      </body>
    </body>
  </worldbody>
  <contact>
    <exclude name="manipuland-base" body1="base" body2="box"/>
  </contact>
  <tendon>
    <spatial name="right_arm::j0::bellows0" class="tendon" rgba="0 0 0 0">
      <site site="right_arm::j0::b0::site0"/>
      <site site="right_arm::j0::b1::site0"/>
      <site site="right_arm::j0::b2::site0"/>
      <site site="right_arm::j0::b3::site0"/>
    </spatial>
    <spatial name="right_arm::j0::bellows1" class="tendon" rgba="0 0 0 0">
      <site site="right_arm::j0::b0::site1"/>
      <site site="right_arm::j0::b1::site1"/>
      <site site="right_arm::j0::b2::site1"/>
      <site site="right_arm::j0::b3::site1"/>
    </spatial>
    <spatial name="right_arm::j0::bellows2" class="tendon" rgba="0 0 0 0">
      <site site="right_arm::j0::b0::site2"/>
      <site site="right_arm::j0::b1::site2"/>
      <site site="right_arm::j0::b2::site2"/>
      <site site="right_arm::j0::b3::site2"/>
    </spatial>
    <spatial name="right_arm::j0::bellows3" class="tendon" rgba="0 0 0 0">
      <site site="right_arm::j0::b0::site3"/>
      <site site="right_arm::j0::b1::site3"/>
      <site site="right_arm::j0::b2::site3"/>
      <site site="right_arm::j0::b3::site3"/>
    </spatial>
    <spatial name="right_arm::j0::bellows0_A" class="tendon">
      <site site="right_arm::j0::b0::site0_A"/>
      <site site="right_arm::j0::b1::site0_A"/>
      <site site="right_arm::j0::b2::site0_A"/>
      <site site="right_arm::j0::b3::site0_A"/>
    </spatial>
    <spatial name="right_arm::j0::bellows0_B" class="tendon">
      <site site="right_arm::j0::b0::site0_B"/>
      <site site="right_arm::j0::b1::site0_B"/>
      <site site="right_arm::j0::b2::site0_B"/>
      <site site="right_arm::j0::b3::site0_B"/>
    </spatial>
    <spatial name="right_arm::j0::bellows1_A" class="tendon">
      <site site="right_arm::j0::b0::site1_A"/>
      <site site="right_arm::j0::b1::site1_A"/>
      <site site="right_arm::j0::b2::site1_A"/>
      <site site="right_arm::j0::b3::site1_A"/>
    </spatial>
    <spatial name="right_arm::j0::bellows1_B" class="tendon">
      <site site="right_arm::j0::b0::site1_B"/>
      <site site="right_arm::j0::b1::site1_B"/>
      <site site="right_arm::j0::b2::site1_B"/>
      <site site="right_arm::j0::b3::site1_B"/>
    </spatial>
    <spatial name="right_arm::j0::bellows2_A" class="tendon">
      <site site="right_arm::j0::b0::site2_A"/>
      <site site="right_arm::j0::b1::site2_A"/>
      <site site="right_arm::j0::b2::site2_A"/>
      <site site="right_arm::j0::b3::site2_A"/>
    </spatial>
    <spatial name="right_arm::j0::bellows2_B" class="tendon">
      <site site="right_arm::j0::b0::site2_B"/>
      <site site="right_arm::j0::b1::site2_B"/>
      <site site="right_arm::j0::b2::site2_B"/>
      <site site="right_arm::j0::b3::site2_B"/>
    </spatial>
    <spatial name="right_arm::j0::bellows3_A" class="tendon">
      <site site="right_arm::j0::b0::site3_A"/>
      <site site="right_arm::j0::b1::site3_A"/>
      <site site="right_arm::j0::b2::site3_A"/>
      <site site="right_arm::j0::b3::site3_A"/>
    </spatial>
    <spatial name="right_arm::j0::bellows3_B" class="tendon">
      <site site="right_arm::j0::b0::site3_B"/>
      <site site="right_arm::j0::b1::site3_B"/>
      <site site="right_arm::j0::b2::site3_B"/>
      <site site="right_arm::j0::b3::site3_B"/>
    </spatial>
    <spatial name="right_arm::j1::bellows0" class="tendon">
      <site site="right_arm::j1::b0::site0"/>
      <site site="right_arm::j1::b1::site0"/>
      <site site="right_arm::j1::b2::site0"/>
      <site site="right_arm::j1::b3::site0"/>
    </spatial>
    <spatial name="right_arm::j1::bellows1" class="tendon">
      <site site="right_arm::j1::b0::site1"/>
      <site site="right_arm::j1::b1::site1"/>
      <site site="right_arm::j1::b2::site1"/>
      <site site="right_arm::j1::b3::site1"/>
    </spatial>
    <spatial name="right_arm::j1::bellows2" class="tendon">
      <site site="right_arm::j1::b0::site2"/>
      <site site="right_arm::j1::b1::site2"/>
      <site site="right_arm::j1::b2::site2"/>
      <site site="right_arm::j1::b3::site2"/>
    </spatial>
    <spatial name="right_arm::j1::bellows3" class="tendon">
      <site site="right_arm::j1::b0::site3"/>
      <site site="right_arm::j1::b1::site3"/>
      <site site="right_arm::j1::b2::site3"/>
      <site site="right_arm::j1::b3::site3"/>
    </spatial>
    <spatial name="right_arm::j2::bellows0" class="tendon">
      <site site="right_arm::j2::b0::site0"/>
      <site site="right_arm::j2::b1::site0"/>
      <site site="right_arm::j2::b2::site0"/>
      <site site="right_arm::j2::b3::site0"/>
    </spatial>
    <spatial name="right_arm::j2::bellows1" class="tendon">
      <site site="right_arm::j2::b0::site1"/>
      <site site="right_arm::j2::b1::site1"/>
      <site site="right_arm::j2::b2::site1"/>
      <site site="right_arm::j2::b3::site1"/>
    </spatial>
    <spatial name="right_arm::j2::bellows2" class="tendon">
      <site site="right_arm::j2::b0::site2"/>
      <site site="right_arm::j2::b1::site2"/>
      <site site="right_arm::j2::b2::site2"/>
      <site site="right_arm::j2::b3::site2"/>
    </spatial>
    <spatial name="right_arm::j2::bellows3" class="tendon">
      <site site="right_arm::j2::b0::site3"/>
      <site site="right_arm::j2::b1::site3"/>
      <site site="right_arm::j2::b2::site3"/>
      <site site="right_arm::j2::b3::site3"/>
    </spatial>
    <spatial name="left_arm::j0::bellows0" class="tendon" rgba="0 0 0 0">
      <site site="left_arm::j0::b0::site0"/>
      <site site="left_arm::j0::b1::site0"/>
      <site site="left_arm::j0::b2::site0"/>
      <site site="left_arm::j0::b3::site0"/>
    </spatial>
    <spatial name="left_arm::j0::bellows1" class="tendon" rgba="0 0 0 0">
      <site site="left_arm::j0::b0::site1"/>
      <site site="left_arm::j0::b1::site1"/>
      <site site="left_arm::j0::b2::site1"/>
      <site site="left_arm::j0::b3::site1"/>
    </spatial>
    <spatial name="left_arm::j0::bellows2" class="tendon" rgba="0 0 0 0">
      <site site="left_arm::j0::b0::site2"/>
      <site site="left_arm::j0::b1::site2"/>
      <site site="left_arm::j0::b2::site2"/>
      <site site="left_arm::j0::b3::site2"/>
    </spatial>
    <spatial name="left_arm::j0::bellows3" class="tendon" rgba="0 0 0 0">
      <site site="left_arm::j0::b0::site3"/>
      <site site="left_arm::j0::b1::site3"/>
      <site site="left_arm::j0::b2::site3"/>
      <site site="left_arm::j0::b3::site3"/>
    </spatial>
    <spatial name="left_arm::j0::bellows0_A" class="tendon">
      <site site="left_arm::j0::b0::site0_A"/>
      <site site="left_arm::j0::b1::site0_A"/>
      <site site="left_arm::j0::b2::site0_A"/>
      <site site="left_arm::j0::b3::site0_A"/>
    </spatial>
    <spatial name="left_arm::j0::bellows0_B" class="tendon">
      <site site="left_arm::j0::b0::site0_B"/>
      <site site="left_arm::j0::b1::site0_B"/>
      <site site="left_arm::j0::b2::site0_B"/>
      <site site="left_arm::j0::b3::site0_B"/>
    </spatial>
    <spatial name="left_arm::j0::bellows1_A" class="tendon">
      <site site="left_arm::j0::b0::site1_A"/>
      <site site="left_arm::j0::b1::site1_A"/>
      <site site="left_arm::j0::b2::site1_A"/>
      <site site="left_arm::j0::b3::site1_A"/>
    </spatial>
    <spatial name="left_arm::j0::bellows1_B" class="tendon">
      <site site="left_arm::j0::b0::site1_B"/>
      <site site="left_arm::j0::b1::site1_B"/>
      <site site="left_arm::j0::b2::site1_B"/>
      <site site="left_arm::j0::b3::site1_B"/>
    </spatial>
    <spatial name="left_arm::j0::bellows2_A" class="tendon">
      <site site="left_arm::j0::b0::site2_A"/>
      <site site="left_arm::j0::b1::site2_A"/>
      <site site="left_arm::j0::b2::site2_A"/>
      <site site="left_arm::j0::b3::site2_A"/>
    </spatial>
    <spatial name="left_arm::j0::bellows2_B" class="tendon">
      <site site="left_arm::j0::b0::site2_B"/>
      <site site="left_arm::j0::b1::site2_B"/>
      <site site="left_arm::j0::b2::site2_B"/>
      <site site="left_arm::j0::b3::site2_B"/>
    </spatial>
    <spatial name="left_arm::j0::bellows3_A" class="tendon">
      <site site="left_arm::j0::b0::site3_A"/>
      <site site="left_arm::j0::b1::site3_A"/>
      <site site="left_arm::j0::b2::site3_A"/>
      <site site="left_arm::j0::b3::site3_A"/>
    </spatial>
    <spatial name="left_arm::j0::bellows3_B" class="tendon">
      <site site="left_arm::j0::b0::site3_B"/>
      <site site="left_arm::j0::b1::site3_B"/>
      <site site="left_arm::j0::b2::site3_B"/>
      <site site="left_arm::j0::b3::site3_B"/>
    </spatial>
    <spatial name="left_arm::j1::bellows0" class="tendon">
      <site site="left_arm::j1::b0::site0"/>
      <site site="left_arm::j1::b1::site0"/>
      <site site="left_arm::j1::b2::site0"/>
      <site site="left_arm::j1::b3::site0"/>
    </spatial>
    <spatial name="left_arm::j1::bellows1" class="tendon">
      <site site="left_arm::j1::b0::site1"/>
      <site site="left_arm::j1::b1::site1"/>
      <site site="left_arm::j1::b2::site1"/>
      <site site="left_arm::j1::b3::site1"/>
    </spatial>
    <spatial name="left_arm::j1::bellows2" class="tendon">
      <site site="left_arm::j1::b0::site2"/>
      <site site="left_arm::j1::b1::site2"/>
      <site site="left_arm::j1::b2::site2"/>
      <site site="left_arm::j1::b3::site2"/>
    </spatial>
    <spatial name="left_arm::j1::bellows3" class="tendon">
      <site site="left_arm::j1::b0::site3"/>
      <site site="left_arm::j1::b1::site3"/>
      <site site="left_arm::j1::b2::site3"/>
      <site site="left_arm::j1::b3::site3"/>
    </spatial>
    <spatial name="left_arm::j2::bellows0" class="tendon">
      <site site="left_arm::j2::b0::site0"/>
      <site site="left_arm::j2::b1::site0"/>
      <site site="left_arm::j2::b2::site0"/>
      <site site="left_arm::j2::b3::site0"/>
    </spatial>
    <spatial name="left_arm::j2::bellows1" class="tendon">
      <site site="left_arm::j2::b0::site1"/>
      <site site="left_arm::j2::b1::site1"/>
      <site site="left_arm::j2::b2::site1"/>
      <site site="left_arm::j2::b3::site1"/>
    </spatial>
    <spatial name="left_arm::j2::bellows2" class="tendon">
      <site site="left_arm::j2::b0::site2"/>
      <site site="left_arm::j2::b1::site2"/>
      <site site="left_arm::j2::b2::site2"/>
      <site site="left_arm::j2::b3::site2"/>
    </spatial>
    <spatial name="left_arm::j2::bellows3" class="tendon">
      <site site="left_arm::j2::b0::site3"/>
      <site site="left_arm::j2::b1::site3"/>
      <site site="left_arm::j2::b2::site3"/>
      <site site="left_arm::j2::b3::site3"/>
    </spatial>
  </tendon>
  <actuator>
    <plugin name="elevator" class="/" plugin="mujoco.actuator.ruckig_actuator" ctrllimited="true" ctrlrange="-1000 0" actdim="2" joint="chest::linear_actuator">
      <config key="kp" value="1000"/>
      <config key="kv" value="1000"/>
      <config key="ka" value="1000"/>
      <config key="max_velocity" value="0.03"/>
      <config key="max_acceleration" value="0.01"/>
      <config key="max_jerk" value="0.05"/>
    </plugin>
    <cylinder name="right_arm::j0::p0" class="cylinder" tendon="right_arm::j0::bellows0" timeconst="0.20000000000000001" area="6"/>
    <cylinder name="right_arm::j0::p1" class="cylinder" tendon="right_arm::j0::bellows1" timeconst="0.20000000000000001" area="6"/>
    <cylinder name="right_arm::j0::p2" class="cylinder" tendon="right_arm::j0::bellows2" timeconst="0.20000000000000001" area="6"/>
    <cylinder name="right_arm::j0::p3" class="cylinder" tendon="right_arm::j0::bellows3" timeconst="0.20000000000000001" area="6"/>
    <cylinder name="right_arm::j1::p0" class="cylinder" tendon="right_arm::j1::bellows0" timeconst="0.20000000000000001" area="4"/>
    <cylinder name="right_arm::j1::p1" class="cylinder" tendon="right_arm::j1::bellows1" timeconst="0.20000000000000001" area="4"/>
    <cylinder name="right_arm::j1::p2" class="cylinder" tendon="right_arm::j1::bellows2" timeconst="0.20000000000000001" area="4"/>
    <cylinder name="right_arm::j1::p3" class="cylinder" tendon="right_arm::j1::bellows3" timeconst="0.20000000000000001" area="4"/>
    <cylinder name="right_arm::j2::p0" class="cylinder" tendon="right_arm::j2::bellows0" timeconst="1" area="4"/>
    <cylinder name="right_arm::j2::p1" class="cylinder" tendon="right_arm::j2::bellows1" timeconst="1" area="4"/>
    <cylinder name="right_arm::j2::p2" class="cylinder" tendon="right_arm::j2::bellows2" timeconst="1" area="4"/>
    <cylinder name="right_arm::j2::p3" class="cylinder" tendon="right_arm::j2::bellows3" timeconst="1" area="4"/>
    <cylinder name="left_arm::j0::p0" class="cylinder" tendon="left_arm::j0::bellows0" timeconst="0.20000000000000001" area="6"/>
    <cylinder name="left_arm::j0::p1" class="cylinder" tendon="left_arm::j0::bellows1" timeconst="0.20000000000000001" area="6"/>
    <cylinder name="left_arm::j0::p2" class="cylinder" tendon="left_arm::j0::bellows2" timeconst="0.20000000000000001" area="6"/>
    <cylinder name="left_arm::j0::p3" class="cylinder" tendon="left_arm::j0::bellows3" timeconst="0.20000000000000001" area="6"/>
    <cylinder name="left_arm::j1::p0" class="cylinder" tendon="left_arm::j1::bellows0" timeconst="0.20000000000000001" area="4"/>
    <cylinder name="left_arm::j1::p1" class="cylinder" tendon="left_arm::j1::bellows1" timeconst="0.20000000000000001" area="4"/>
    <cylinder name="left_arm::j1::p2" class="cylinder" tendon="left_arm::j1::bellows2" timeconst="0.20000000000000001" area="4"/>
    <cylinder name="left_arm::j1::p3" class="cylinder" tendon="left_arm::j1::bellows3" timeconst="0.20000000000000001" area="4"/>
    <cylinder name="left_arm::j2::p0" class="cylinder" tendon="left_arm::j2::bellows0" timeconst="1" area="4"/>
    <cylinder name="left_arm::j2::p1" class="cylinder" tendon="left_arm::j2::bellows1" timeconst="1" area="4"/>
    <cylinder name="left_arm::j2::p2" class="cylinder" tendon="left_arm::j2::bellows2" timeconst="1" area="4"/>
    <cylinder name="left_arm::j2::p3" class="cylinder" tendon="left_arm::j2::bellows3" timeconst="1" area="4"/>
  </actuator>
  <sensor>
    <framequat name="right_arm::j0::B0_framequat" objtype="body" objname="right_arm::j0::B0"/>
    <framequat name="right_arm::j0::B3_framequat" objtype="body" objname="right_arm::j0::B3"/>
    <frameangvel name="right_arm::j0::B3_frameangvel" objtype="body" objname="right_arm::j0::B3" reftype="body" refname="right_arm::j0::B0"/>
    <plugin name="right_arm::j0" plugin="mujoco.sensor.joint_angle_estimator"/>
    <tendonpos name="right_arm::j0::bellows0" tendon="right_arm::j0::bellows0"/>
    <tendonpos name="right_arm::j0::bellows1" tendon="right_arm::j0::bellows1"/>
    <tendonpos name="right_arm::j0::bellows2" tendon="right_arm::j0::bellows2"/>
    <tendonpos name="right_arm::j0::bellows3" tendon="right_arm::j0::bellows3"/>
    <framequat name="right_arm::j1::B0_framequat" objtype="body" objname="right_arm::j1::B0"/>
    <framequat name="right_arm::j1::B3_framequat" objtype="body" objname="right_arm::j1::B3"/>
    <frameangvel name="right_arm::j1::B3_frameangvel" objtype="body" objname="right_arm::j1::B3" reftype="body" refname="right_arm::j1::B0"/>
    <plugin name="right_arm::j1" plugin="mujoco.sensor.joint_angle_estimator"/>
    <tendonpos name="right_arm::j1::bellows0" tendon="right_arm::j1::bellows0"/>
    <tendonpos name="right_arm::j1::bellows1" tendon="right_arm::j1::bellows1"/>
    <tendonpos name="right_arm::j1::bellows2" tendon="right_arm::j1::bellows2"/>
    <tendonpos name="right_arm::j1::bellows3" tendon="right_arm::j1::bellows3"/>
    <framequat name="right_arm::j2::B0_framequat" objtype="body" objname="right_arm::j2::B0"/>
    <framequat name="right_arm::j2::B3_framequat" objtype="body" objname="right_arm::j2::B3"/>
    <frameangvel name="right_arm::j2::B3_frameangvel" objtype="body" objname="right_arm::j2::B3" reftype="body" refname="right_arm::j2::B0"/>
    <plugin name="right_arm::j2" plugin="mujoco.sensor.joint_angle_estimator"/>
    <tendonpos name="right_arm::j2::bellows0" tendon="right_arm::j2::bellows0"/>
    <tendonpos name="right_arm::j2::bellows1" tendon="right_arm::j2::bellows1"/>
    <tendonpos name="right_arm::j2::bellows2" tendon="right_arm::j2::bellows2"/>
    <tendonpos name="right_arm::j2::bellows3" tendon="right_arm::j2::bellows3"/>
    <framequat name="left_arm::j0::B0_framequat" objtype="body" objname="left_arm::j0::B0"/>
    <framequat name="left_arm::j0::B3_framequat" objtype="body" objname="left_arm::j0::B3"/>
    <frameangvel name="left_arm::j0::B3_frameangvel" objtype="body" objname="left_arm::j0::B3" reftype="body" refname="left_arm::j0::B0"/>
    <plugin name="left_arm::j0" plugin="mujoco.sensor.joint_angle_estimator"/>
    <tendonpos name="left_arm::j0::bellows0" tendon="left_arm::j0::bellows0"/>
    <tendonpos name="left_arm::j0::bellows1" tendon="left_arm::j0::bellows1"/>
    <tendonpos name="left_arm::j0::bellows2" tendon="left_arm::j0::bellows2"/>
    <tendonpos name="left_arm::j0::bellows3" tendon="left_arm::j0::bellows3"/>
    <framequat name="left_arm::j1::B0_framequat" objtype="body" objname="left_arm::j1::B0"/>
    <framequat name="left_arm::j1::B3_framequat" objtype="body" objname="left_arm::j1::B3"/>
    <frameangvel name="left_arm::j1::B3_frameangvel" objtype="body" objname="left_arm::j1::B3" reftype="body" refname="left_arm::j1::B0"/>
    <plugin name="left_arm::j1" plugin="mujoco.sensor.joint_angle_estimator"/>
    <tendonpos name="left_arm::j1::bellows0" tendon="left_arm::j1::bellows0"/>
    <tendonpos name="left_arm::j1::bellows1" tendon="left_arm::j1::bellows1"/>
    <tendonpos name="left_arm::j1::bellows2" tendon="left_arm::j1::bellows2"/>
    <tendonpos name="left_arm::j1::bellows3" tendon="left_arm::j1::bellows3"/>
    <framequat name="left_arm::j2::B0_framequat" objtype="body" objname="left_arm::j2::B0"/>
    <framequat name="left_arm::j2::B3_framequat" objtype="body" objname="left_arm::j2::B3"/>
    <frameangvel name="left_arm::j2::B3_frameangvel" objtype="body" objname="left_arm::j2::B3" reftype="body" refname="left_arm::j2::B0"/>
    <plugin name="left_arm::j2" plugin="mujoco.sensor.joint_angle_estimator"/>
    <tendonpos name="left_arm::j2::bellows0" tendon="left_arm::j2::bellows0"/>
    <tendonpos name="left_arm::j2::bellows1" tendon="left_arm::j2::bellows1"/>
    <tendonpos name="left_arm::j2::bellows2" tendon="left_arm::j2::bellows2"/>
    <tendonpos name="left_arm::j2::bellows3" tendon="left_arm::j2::bellows3"/>
  </sensor>
</mujoco>
