<mujoco model="test">
  <compiler angle="degree" inertiafromgeom="true"/>
  <option timestep="0.01" integrator="implicitfast" cone="elliptic" jacobian="sparse" solver="Newton">
    <flag gravity="enable"/>
  </option>
  <size njmax="5000" nconmax="5000" nstack="5000000"/>
  <visual>
    <map stiffness="100" fogstart="10" fogend="15" zfar="40" shadowscale="0.5"/>
    <scale forcewidth="0.10000000000000001" contactwidth="0.074999999999999997" contactheight="0.025000000000000001" framelength="0.59999999999999998" framewidth="0.059999999999999998"/>
  </visual>
  <default>
    <default class="/"/>
  </default>
  <asset>
    <texture name="texplane" type="2d" builtin="checker" mark="cross" width="512" height="512"/>
    <material name="matplane" class="/" texture="texplane" texuniform="true"/>
  </asset>
  <worldbody>
    <geom name="world" class="/" type="plane" condim="1" size="0 0 1" material="matplane"/>
    <light name="//unnamed_light_0" class="/" directional="true" pos="0 0 4" dir="0 0 -1" diffuse="0.59999999999999998 0.59999999999999998 0.59999999999999998" specular="0.20000000000000001 0.20000000000000001 0.20000000000000001"/>
    <camera name="fixedcam" class="/" pos="-1.357 2.722 2.4470000000000001" xyaxes="-0.88200000000000001 -0.47199999999999998 0 0.23799999999999999 -0.44600000000000001 0.86299999999999999"/>
    <body name="pendulum" pos="0 0 0.10000000000000001" euler="0 90 0">
      <geom name="//unnamed_geom_1" class="/" type="capsule" size="0.050000000000000003 0.5" fromto="0 0 0 0 0 1"/>
      <inertial pos="0 0 0.5" mass="1"/>
      <joint name="joint" class="/" pos="0 0 0" axis="1 0 0" springdamper="0.5 0.20000000000000001"/>
    </body>
  </worldbody>
  <actuator>
    <position name="velocity_servo" class="/" joint="joint" kp="50000" kv="500"/>
  </actuator>
</mujoco>
